Workbook

Sheet Sources and Uses Existing
B2: Sources and Uses of Funds
B4: Acquisition Assumptions | F4: Lender | G4: Amount | H4: Interest Rate | I4: Term | J4: Monthly Payment | L4: Principal Reduction | M4: Year 1 | N4: Year 2 | O4: Year 3 | P4: Year 4 | Q4: Year 5
B5: Total Project Cost | D5: =4200000-G27 -> 3700000 | F5: 1st Position | G5: =D6 -> 2775000 | H5: 0.065 | I5: 25 | J5: =PMT(H5/12,I5*12,-G5,0,0) -> 18736.999 | M5: =iferror(CUMPRINC(H5/12,I5*12,G5,1,12,0),"") -> -45818.004 | N5: =iferror(CUMPRINC(H5/12,I5*12,G5,13,24,0),"") -> -48886.521 | O5: =iferror(CUMPRINC(H5/12,I5*12,G5,25,36,0),"") -> -52160.541 | P5: =iferror(CUMPRINC(H5/12,I5*12,G5,37,48,0),"") -> -55653.83 | Q5: =iferror(CUMPRINC(H5/12,I5*12,G5,49,60,0),"") -> -59381.07
B6: 1st Position Loan (Bank) | C6: 0.75 | D6: =C6*D5 -> 2775000 | F6: 2nd Position | G6: =D7 -> 0 | H6: 0.0675 | I6: 25 | J6: =PMT(H6/12,I6*12,-G6,0,1) -> 0 | M6: =iferror(CUMPRINC(H6/12,I6*12,G6,1,12,0),"") | N6: =iferror(CUMPRINC(H6/12,I6*12,G6,13,24,0),"") | O6: =iferror(CUMPRINC(H6/12,I6*12,G6,25,36,0),"") | P6: =iferror(CUMPRINC(H6/12,I6*12,G6,37,48,0),"") | Q6: =iferror(CUMPRINC(H6/12,I6*12,G6,49,60,0),"")
B7: 2nd Position Loan (SBA) | C7: 0 | D7: =C7*D5 -> 0 | F7: Seller | G7: =D8 -> 0 | H7: 0.05 | I7: 25 | J7: =PMT(H7/12,I7*12,-G7,0,1) -> 0 | M7: =iferror(CUMPRINC(H7/12,I7*12,G7,1,12,0),"") | N7: =iferror(CUMPRINC(H7/12,I7*12,G7,13,24,0),"") | O7: =iferror(CUMPRINC(H7/12,I7*12,G7,25,36,0),"") | P7: =iferror(CUMPRINC(H7/12,I7*12,G7,37,48,0),"") | Q7: =iferror(CUMPRINC(H7/12,I7*12,G7,49,60,0),"")
B8: 3rd Position Seller Finance | C8: 0 | D8: =C8*D5 -> 0 | F8: Total | G8: =G6+G5+G7 -> 2775000 | I8: Monthly Debt Service | J8: =J6+J5+J7 -> 18736.999 | L8: Total Principal Reduction | M8: =sum(M5:M7) -> -45818.004 | N8: =sum(N5:N7) -> -48886.521 | O8: =sum(O5:O7) -> -52160.541 | P8: =sum(P5:P7) -> -55653.83 | Q8: =sum(Q5:Q7) -> -59381.07
B9: Total Debt | D9: =D8+D7+D6 -> 2775000 | I9: Annual Debt Service | J9: =J8*12 -> 224843.98 | L9: Loan Balance | M9: =G8+M8 -> 2729182 | N9: =N8+M9 -> 2680295.5 | O9: =O8+N9 -> 2628134.9 | P9: =P8+O9 -> 2572481.1 | Q9: =Q8+P9 -> 2513100
B10: Down Payment | D10: =D5-D6-D7-D8 -> 925000
B11: Reserve | C11: 0.03 | D11: =D5*C11 -> 111000 | G11: =Proforma!H49 -> 0.08819807 | J11: =J5-16443.62 -> 2293.3787
B12: Fees | D12: =D23 -> 254375
B13: Total Equity | D13: =D12+D11+D10 -> 1290375 | J13: 23588.76 | M13: =M8/$G$20 -> -0.035507511 | N13: =N8/$G$20 -> -0.037885514 | O13: =O8/$G$20 -> -0.040422777 | P13: =P8/$G$20 -> -0.043129966 | Q13: =Q8/$G$20 -> -0.046018459
B14: Total Sources and Uses | D14: =D13+D9 -> 4065375 | J14: =J13*12 -> 283065.12
B16: Fees | F16: Sources and Uses of Funds
B17: Bank Fees | C17: 0.015 | D17: =C17*D9 -> 41625 | F17: Bank Required Down Payment | G17: =D10 -> 925000
B18: Vega Capital Markets Fee | C18: 0.01 | D18: =C18*D9 -> 27750 | F18: Fees | G18: =D23 -> 254375
B19: Acquisition Fee | C19: 0.03 | D19: =C19*D5 -> 111000 | F19: Reserve | G19: =D11 -> 111000
B20: Due Diligence Costs | C20: 0.01 | D20: =C20*D5 -> 37000 | F20: Total | G20: =SUM(G17:G19) -> 1290375
B21: Closing Costs | C21: 0.01 | D21: =C21*D5 -> 37000
B23: Total | D23: =SUM(D17:D22) -> 254375
F27: Value of Land | G27: 500000
G32: =G20+'Sources and Uses New'!G20 -> 2633062.5
G34: 719000 | H34: =G34/G20 -> 0.55720236 | I34: =H34*D5 -> 2061648.7
G35: 127000
G36: =G34-G35 -> 592000 | H36: =G36/G20 -> 0.45878136
G37: =G36/G20 -> 0.45878136 | H37: =G37*D5 -> 1697491 | J37: 3280000
J38: =0.6273*J37 -> 2057544 | L38: =J38-H37 -> 360052.96
I55: Sale Price | J55: Share of Price | L55: Percent of Total | M55: Percent Required of Purchase Price
B56: Purchase Price | D56: =D5+'Sources and Uses New'!G25 -> 4200000 | G56: Rob Hanks | H56: 606885.17 | I56: =J38 -> 2057544 | J56: =L56*$D$56 -> 968043 | L56: =H56/$H$63 -> 0.23048643 | M56: =I56/$D$56 -> 0.48989143 | Q56: =2541500 -> 2541500
B57: Construction | D57: 3350000 | G57: Greg Waddoups | H57: 269127.43 | I57: 675000 | J57: =L57*$D$56 -> 429285.37 | L57: =H57/$H$63 -> 0.1022108 | M57: =I57/$D$56 -> 0.16071429 | Q57: =H56/Q56 -> 0.23879015
B58: Total | D58: =D57+D56 -> 7550000 | G58: Fund II | H58: =2517563-1151012.6 -> 1366550.4 | L58: =H58/$H$63 -> 0.51899657 | M58: =1-0.7296 -> 0.2704
B59: Down @ 25% | D59: =D58*0.25 -> 1887500 | G59: Crawford | H59: 275000 | I59: =995000/3 -> 331666.67 | J59: =L59*$D$56 -> 438652.71 | L59: =H59/$H$63 -> 0.10444112 | M59: =I59/$D$56 -> 0.078968254
B60: Down @ 30% | D60: =D58*0.3 -> 2265000 | G60: Total | H60: =sum(H56:H59) -> 2517563 | I60: =D60-H60 -> -252563 | L60: =sum(L56:L59) -> 0.95613492 | M60: =sum(M56:M59) -> 0.99997397
G61: Mike Peterson | H61: =I61*0.99 -> 897930 | I61: 907000
H63: ='Sources and Uses New'!G20+G20 -> 2633062.5 | I63: =H63-H60 -> 115499.5 | J63: =H56/$H$63 -> 0.23048643

Sheet Payroll
A1: Position | B1: Employee | C1: Pay Period Earnings ($) | D1: Annualized Pay ($) | E1: Notes | F1: Payroll needed for new facility
A2: Administrator | B2: Shauna Keadle | C2: 2544.7 | D2: 66162.2
A3: Caregiver | B3: Tailynn Burcham | C3: 1454.6 | D3: 37819.6 | F3: =D3 -> 37819.6
A4: Caregiver | B4: Maria Diaz | C4: 1379.88 | D4: 35876.88 | F4: =D4 -> 35876.88
A5: Caregiver | B5: Tamara Hewett | C5: 1951.09 | D5: 50728.34 | F5: =D5 -> 50728.34
A6: Caregiver | B6: Melissa Hilton | C6: 1560.72 | D6: 40578.72 | F6: =D6 -> 40578.72
A7: Caregiver | B7: Austin Hoskins | C7: 919.6 | D7: 23909.6 | F7: =D7 -> 23909.6
A8: Caregiver | B8: Joel Nangitngitan | C8: 2525.6 | D8: 65665.6 | F8: =D8 -> 65665.6
A9: Caregiver | B9: Karen Njoroge | C9: 1647.68 | D9: 42839.68 | F9: =D9 -> 42839.68
A10: Caregiver | B10: Paul Piperata | C10: 1347.57 | D10: 35036.82 | F10: =D10 -> 35036.82
A11: Caregiver | B11: Garry Ramos | C11: 581.49 | D11: 15118.74 | F11: =D11 -> 15118.74
A12: Caregiver | B12: Michelle Rodriguez | C12: 1772.93 | D12: 46096.18 | F12: =D12 -> 46096.18
A13: Caregiver | B13: Ervina Tacheene | C13: 1888.99 | D13: 49113.74 | F13: =D13 -> 49113.74
A14: Caregiver | B14: Aliyah Wright | C14: 2389.59 | D14: 62129.34 | F14: =D14 -> 62129.34
A15: Activities Director | B15: Alyssa Gutierrez | C15: 1252.35 | D15: 32561.1
A16: Nurse | B16: Klaudia McClory | C16: 2980.8 | D16: 77500.8 | E16: Why full time nurse? Required by law? According to ChatGPT. No
A17: Assistant Caregiver | B17: Gabrielle McCloskey | C17: 750 | D17: 19500 | F17: =D17 -> 19500
A18: Assistant Caregiver | B18: Kiersten Tsosie | C18: 893.16 | D18: 23222.16 | F18: =D18 -> 23222.16
A19: Cook | B19: Kayla Hines | C19: 1794 | D19: 46644
A20: Cook | B20: Andrew Sala | C20: 1638 | D20: 42588 | E20: Why two cooks
C21: =sum(C2:C20) -> 31272.75 | D21: =sum(D2:D20) -> 813091.5 | E21: =D21-D20-D16-D14-D13 -> 581759.62 | F21: =sum(F2:F20) -> 547635.4
D23: 700000
E24: =D21-E21 -> 231331.88
C25: Need to cut? | D25: =D21-D23 -> 113091.5

Sheet Sources and Uses New
B2: Sources and Uses of Funds
B4: Acquisition Assumptions | F4: Lender | G4: Amount | H4: Interest Rate | I4: Term | J4: Monthly Payment | L4: Principal Reduction | M4: Year 1 | N4: Year 2 | O4: Year 3 | P4: Year 4 | Q4: Year 5
B5: Total Project Cost | D5: =G28 -> 3850000 | F5: 1st Position | G5: =D6 -> 2887500 | H5: 0.065 | I5: 25 | J5: =PMT(H5/12,I5*12,-G5,0,0) -> 19496.607 | M5: =iferror(CUMPRINC(H5/12,I5*12,G5,1,12,0),"") -> -47675.491 | N5: =iferror(CUMPRINC(H5/12,I5*12,G5,13,24,0),"") -> -50868.407 | O5: =iferror(CUMPRINC(H5/12,I5*12,G5,25,36,0),"") -> -54275.158 | P5: =iferror(CUMPRINC(H5/12,I5*12,G5,37,48,0),"") -> -57910.066 | Q5: =iferror(CUMPRINC(H5/12,I5*12,G5,49,60,0),"") -> -61788.41
B6: 1st Position Loan (Bank) | C6: 0.75 | D6: =C6*D5 -> 2887500 | F6: 2nd Position | G6: =D7 -> 0 | H6: 0.0675 | I6: 25 | J6: =PMT(H6/12,I6*12,-G6,0,1) -> 0 | M6: =iferror(CUMPRINC(H6/12,I6*12,G6,1,12,0),"") | N6: =iferror(CUMPRINC(H6/12,I6*12,G6,13,24,0),"") | O6: =iferror(CUMPRINC(H6/12,I6*12,G6,25,36,0),"") | P6: =iferror(CUMPRINC(H6/12,I6*12,G6,37,48,0),"") | Q6: =iferror(CUMPRINC(H6/12,I6*12,G6,49,60,0),"")
B7: 2nd Position Loan (SBA) | C7: 0 | D7: =C7*D5 -> 0 | F7: Seller | G7: =D8 -> 0 | H7: 0.05 | I7: 25 | J7: =PMT(H7/12,I7*12,-G7,0,1) -> 0 | M7: =iferror(CUMPRINC(H7/12,I7*12,G7,1,12,0),"") | N7: =iferror(CUMPRINC(H7/12,I7*12,G7,13,24,0),"") | O7: =iferror(CUMPRINC(H7/12,I7*12,G7,25,36,0),"") | P7: =iferror(CUMPRINC(H7/12,I7*12,G7,37,48,0),"") | Q7: =iferror(CUMPRINC(H7/12,I7*12,G7,49,60,0),"")
B8: 3rd Position Seller Finance | C8: 0 | D8: =C8*D5 -> 0 | F8: Total | G8: =G6+G5+G7 -> 2887500 | I8: Monthly Debt Service | J8: =J6+J5+J7 -> 19496.607 | L8: Total Principal Reduction | M8: =sum(M5:M7) -> -47675.491 | N8: =sum(N5:N7) -> -50868.407 | O8: =sum(O5:O7) -> -54275.158 | P8: =sum(P5:P7) -> -57910.066 | Q8: =sum(Q5:Q7) -> -61788.41
B9: Total Debt | D9: =D8+D7+D6 -> 2887500 | I9: Annual Debt Service | J9: =J8*12 -> 233959.28 | L9: Loan Balance | M9: =G8+M8 -> 2839824.5 | N9: =N8+M9 -> 2788956.1 | O9: =O8+N9 -> 2734680.9 | P9: =P8+O9 -> 2676770.9 | Q9: =Q8+P9 -> 2614982.5
B10: Down Payment | D10: =D5-D6-D7-D8 -> 962500
B11: Reserve | C11: 0.03 | D11: =D5*C11 -> 115500 | G11: =Proforma!H49 -> 0.08819807 | J11: =J5-16443.62 -> 3052.9868
B12: Fees | D12: =D23 -> 264687.5
B13: Total Equity | D13: =D12+D11+D10 -> 1342687.5 | J13: 23588.76 | M13: =M8/$G$20 -> -0.035507511 | N13: =N8/$G$20 -> -0.037885514 | O13: =O8/$G$20 -> -0.040422777 | P13: =P8/$G$20 -> -0.043129966 | Q13: =Q8/$G$20 -> -0.046018459
B14: Total Sources and Uses | D14: =D13+D9 -> 4230187.5 | J14: =J13*12 -> 283065.12
B16: Fees | F16: Sources and Uses of Funds
B17: Bank Fees | C17: 0.015 | D17: =C17*D9 -> 43312.5 | F17: Bank Required Down Payment | G17: =D10 -> 962500
B18: Vega Capital Markets Fee | C18: 0.01 | D18: =C18*D9 -> 28875 | F18: Fees | G18: =D23 -> 264687.5
B19: Acquisition Fee | C19: 0.03 | D19: =C19*D5 -> 115500 | F19: Reserve | G19: =D11 -> 115500
B20: Due Diligence Costs | C20: 0.01 | D20: =C20*D5 -> 38500 | F20: Total | G20: =SUM(G17:G19) -> 1342687.5
B21: Closing Costs | C21: 0.01 | D21: =C21*D5 -> 38500
B23: Total | D23: =SUM(D17:D22) -> 264687.5
F24: New Building
F25: Land Cost | G25: ='Sources and Uses Existing'!G27 -> 500000 | H25: <--- included in purchase price
F26: Building Cost | G26: 3000000
F27: Soft Costs | G27: =(G26+G25)*0.1 -> 350000
F28: Total | G28: =SUM(G25:G27) -> 3850000
F29: Square Feet of New Building | G29: 11200
F33: Estimated Construction Costs
F34: Construction Plans

Sheet Proforma
C2: 3 Year Historicals (Actuals) | O2: 22 rooms 24 beds
C4: Year | D4: 2022 | E4: 2023 | F4: 2024 | G4: 2025 YTD (Sept) | H4: 2025 | I4: Proforma Year 1 | J4: Proforma Year 2 | K4: Proforma Year 3 | L4: Proforma Year 4 | M4: Proforma Year 5
C5: Potential Income | E5: 1580473.3 | F5: 1531957.7 | G5: 1231955.3 | H5: 1654595 | I5: 1800000 | J5: =I5*1.03 -> 1854000 | K5: =J5*1.03 -> 1909620 | L5: =K5*1.03 -> 1966908.6 | M5: =L5*1.03 -> 2025915.9
C6: Vacancy | E6: -65170.79 | F6: -79288.36 | G6: -58302.16 | H6: -63526.84 | I6: =-I5*0.1 -> -180000 | J6: =I6*1.03 -> -185400 | K6: =J6*1.03 -> -190962 | L6: =K6*1.03 -> -196690.86 | M6: =L6*1.03 -> -202591.59
C7: Income | J7: =I7*1.03 -> 0 | K7: =J7*1.03 -> 0 | L7: =K7*1.03 -> 0 | M7: =L7*1.03 -> 0
C8: Day Care | I8: 2500 | J8: =I8*1.03 -> 2575 | K8: =J8*1.03 -> 2652.25 | L8: =K8*1.03 -> 2731.8175 | M8: =L8*1.03 -> 2813.772
C9: Other Income | E9: 47.89 | F9: 1551.04 | I9: 2500 | J9: =I9*1.03 -> 2575 | K9: =J9*1.03 -> 2652.25 | L9: =K9*1.03 -> 2731.8175 | M9: =L9*1.03 -> 2813.772
C10: Rental Income | J10: =I10*1.03 -> 0 | K10: =J10*1.03 -> 0 | L10: =K10*1.03 -> 0 | M10: =L10*1.03 -> 0
C11: Move In Fees | I11: 2500 | J11: =I11*1.03 -> 2575 | K11: =J11*1.03 -> 2652.25 | L11: =K11*1.03 -> 2731.8175 | M11: =L11*1.03 -> 2813.772
C12: Total Income | D12: =SUM(D8:D11) -> 0 | E12: =SUM(E5:E11) -> 1515350.4 | F12: =SUM(F5:F11) -> 1454220.4 | G12: =SUM(G5:G11) -> 1173653.1 | H12: =SUM(H5:H11) -> 1591068.2 | I12: =SUM(I5:I11) -> 1627500 | J12: =I12*1.03 -> 1676325 | K12: =J12*1.03 -> 1726614.8 | L12: =K12*1.03 -> 1778413.2 | M12: =L12*1.03 -> 1831765.6 | O12: =I12*0.05 -> 81375 | P12: =55*4000 -> 220000 | Q12: =P12*12 -> 2640000 | R12: =Q12*0.95 -> 2508000 | S12: =R12*0.05 -> 125400
J13: =I13*1.03 -> 0 | K13: =J13*1.03 -> 0 | L13: =K13*1.03 -> 0 | M13: =L13*1.03 -> 0
C14: Expenses | J14: =I14*1.03 -> 0 | K14: =J14*1.03 -> 0 | L14: =K14*1.03 -> 0 | M14: =L14*1.03 -> 0
C15: Accounting | E15: 4746.7 | F15: 4979.45 | G15: =4629.45+2500 -> 7129.45 | H15: 9825.95 | I15: 7000 | J15: =I15*1.03 -> 7210 | K15: =J15*1.03 -> 7426.3 | L15: =K15*1.03 -> 7649.089 | M15: =L15*1.03 -> 7878.5617
C16: Advertising/Promotional | E16: =3400+450 -> 3850 | F16: 4991.71 | G16: 1685.85 | H16: 2865.85 | I16: 3500 | J16: =I16*1.03 -> 3605 | K16: =J16*1.03 -> 3713.15 | L16: =K16*1.03 -> 3824.5445 | M16: =L16*1.03 -> 3939.2808
C17: Bank Charges | E17: 378.13 | F17: =138.92+115.22 -> 254.14 | G17: 93.95 | H17: 205.76 | I17: 250 | J17: =I17*1.03 -> 257.5 | K17: =J17*1.03 -> 265.225 | L17: =K17*1.03 -> 273.18175 | M17: =L17*1.03 -> 281.3772
C18: Business licenses/Permits | E18: 2820 | F18: 2820 | G18: 2770 | H18: 2835 | I18: 2820 | J18: =I18*1.03 -> 2904.6 | K18: =J18*1.03 -> 2991.738 | L18: =K18*1.03 -> 3081.4901 | M18: =L18*1.03 -> 3173.9348
C19: Nursing | E19: 22787.88 | F19: 264 | G19: 0 | H19: 0 | I19: 20000 | J19: =I19*1.03 -> 20600 | K19: =J19*1.03 -> 21218 | L19: =K19*1.03 -> 21854.54 | M19: =L19*1.03 -> 22510.176
C20: Dietician | J20: =I20*1.03 -> 0 | K20: =J20*1.03 -> 0 | L20: =K20*1.03 -> 0 | M20: =L20*1.03 -> 0
C21: Dues & Subscriptions | E21: 2211.26 | F21: 1460.6 | G21: 691.81 | H21: 1105.93 | I21: 1500 | J21: =I21*1.03 -> 1545 | K21: =J21*1.03 -> 1591.35 | L21: =K21*1.03 -> 1639.0905 | M21: =L21*1.03 -> 1688.2632
C22: Administrator Expense | J22: =I22*1.03 -> 0 | K22: =J22*1.03 -> 0 | L22: =K22*1.03 -> 0 | M22: =L22*1.03 -> 0
C23: Employee Expenses | E23: =899487.13+4412.55+460.29+3428.39 -> 907788.36 | F23: =842457.45+4307.25+848.85+4377 -> 851990.55 | G23: =683765.18+3287.94 -> 687053.12 | H23: =888880.02+1127.83+616.8+4334.1 -> 894958.75 | I23: 700000 | J23: =I23*1.03 -> 721000 | K23: =J23*1.03 -> 742630 | L23: =K23*1.03 -> 764908.9 | M23: =L23*1.03 -> 787856.17 | O23: =H23-I23 -> 194958.75
C24: Franchise Fees | E24: 27500.5 | F24: 38520.78 | H24: 66922.1 | I24: =I12*0.05 -> 81375 | J24: =J12*0.05 -> 83816.25 | K24: =J24*1.03 -> 86330.738 | L24: =K24*1.03 -> 88920.66 | M24: =L24*1.03 -> 91588.279 | T24: =10*50000 -> 500000
C25: Cleaning | J25: =I25*1.03 -> 0 | K25: =J25*1.03 -> 0 | L25: =K25*1.03 -> 0 | M25: =L25*1.03 -> 0 | T25: =125000*10 -> 1250000
C26: Household Supplies | E26: 27838.81 | F26: 26362.52 | G26: 20031.53 | H26: 25181.72 | I26: 27000 | J26: =I26*1.03 -> 27810 | K26: =J26*1.03 -> 28644.3 | L26: =K26*1.03 -> 29503.629 | M26: =L26*1.03 -> 30388.738
C27: Management Fees | J27: =I27*1.03 -> 0 | K27: =J27*1.03 -> 0 | L27: =K27*1.03 -> 0 | M27: =L27*1.03 -> 0
C28: General business expenses | F28: 1729.5 | G28: 480 | H28: 480 | I28: 1500 | J28: =I28*1.03 -> 1545 | K28: =J28*1.03 -> 1591.35 | L28: =K28*1.03 -> 1639.0905 | M28: =L28*1.03 -> 1688.2632
C29: Insurance | E29: 24117.24 | F29: 22980.06 | G29: 15741.86 | H29: 26085.12 | I29: 25000 | J29: =I29*1.03 -> 25750 | K29: =J29*1.03 -> 26522.5 | L29: =K29*1.03 -> 27318.175 | M29: =L29*1.03 -> 28137.72
C30: Liability insurance | E30: 3680.76 | F30: 0 | J30: =I30*1.03 -> 0 | K30: =J30*1.03 -> 0 | L30: =K30*1.03 -> 0 | M30: =L30*1.03 -> 0
C31: Property insurance | J31: =I31*1.03 -> 0 | K31: =J31*1.03 -> 0 | L31: =K31*1.03 -> 0 | M31: =L31*1.03 -> 0
C32: Lease Payments - Equipment | E32: 700 | F32: 2350.04 | G32: 1470.95 | H32: 1761.79 | I32: 2400 | J32: =I32*1.03 -> 2472 | K32: =J32*1.03 -> 2546.16 | L32: =K32*1.03 -> 2622.5448 | M32: =L32*1.03 -> 2701.2211
C33: Medical Supplies | E33: 8832.36 | F33: 12752.51 | G33: 12588.32 | H33: 17778.69 | I33: 15000 | J33: =I33*1.03 -> 15450 | K33: =J33*1.03 -> 15913.5 | L33: =K33*1.03 -> 16390.905 | M33: =L33*1.03 -> 16882.632
C34: Office expenses | E34: =8014.19+819.43+1733.99+59.17+21.65+217.9 -> 10866.33 | F34: =5927.5+914.8+1303.92+72.24 -> 8218.46 | G34: 5629.31 | H34: =4093.68+46.35+721.84+1477.34+50.43 -> 6389.64 | I34: 5000 | J34: =I34*1.03 -> 5150 | K34: =J34*1.03 -> 5304.5 | L34: =K34*1.03 -> 5463.635 | M34: =L34*1.03 -> 5627.5441
C35: Operations Contract Service | J35: =I35*1.03 -> 0 | K35: =J35*1.03 -> 0 | L35: =K35*1.03 -> 0 | M35: =L35*1.03 -> 0
C36: Placement Fees | E36: 37249.2 | F36: 12021 | G36: 9555.5 | H36: 8856.5 | I36: 15000 | J36: =I36*1.03 -> 15450 | K36: =J36*1.03 -> 15913.5 | L36: =K36*1.03 -> 16390.905 | M36: =L36*1.03 -> 16882.632
C37: Raw Food | E37: =84071.27+380.14 -> 84451.41 | F37: =324+72123.98+1275.57 -> 73723.55 | G37: 67579.16 | H37: =605.41+90342.91 -> 90948.32 | I37: 90000 | J37: =I37*1.03 -> 92700 | K37: =J37*1.03 -> 95481 | L37: =K37*1.03 -> 98345.43 | M37: =L37*1.03 -> 101295.79
C38: Repairs & maintenance | E38: =20934.98 -> 20934.98 | F38: =251.21+28758.52 -> 29009.73 | G38: =98.93+47797.23 -> 47896.16 | H38: =98.93+60942.33 -> 61041.26 | I38: 35000 | J38: =I38*1.03 -> 36050 | K38: =J38*1.03 -> 37131.5 | L38: =K38*1.03 -> 38245.445 | M38: =L38*1.03 -> 39392.808
C39: Resident Activities | E39: 3015.83 | F39: 1252.89 | G39: 6301.37 | H39: 8153.3 | I39: 5000 | J39: =I39*1.03 -> 5150 | K39: =J39*1.03 -> 5304.5 | L39: =K39*1.03 -> 5463.635 | M39: =L39*1.03 -> 5627.5441
C40: Taxes paid | J40: =I40*1.03 -> 0 | K40: =J40*1.03 -> 0 | L40: =K40*1.03 -> 0 | M40: =L40*1.03 -> 0
C41: Property taxes | I41: 12000 | J41: =I41*1.03 -> 12360 | K41: =J41*1.03 -> 12730.8 | L41: =K41*1.03 -> 13112.724 | M41: =L41*1.03 -> 13506.106
C42: Personal Property Taxes | J42: =I42*1.03 -> 0 | K42: =J42*1.03 -> 0 | L42: =K42*1.03 -> 0 | M42: =L42*1.03 -> 0
...

Sheet Proforma New Build
C2: 3 Year Historicals (Actuals)
C4: Year | D4: 2022 | E4: 2023 | F4: 2024 | G4: 2025 YTD (Sept) | H4: 2025 Annualized | I4: Proforma Year 1 | J4: Proforma Year 2 | K4: Proforma Year 3 | L4: Proforma Year 4 | M4: Proforma Year 5
C5: Potential Income | I5: 1296000 | J5: =I5*1.03 -> 1334880 | K5: =J5*1.03 -> 1374926.4 | L5: =K5*1.03 -> 1416174.2 | M5: =L5*1.03 -> 1458659.4
C6: Vacancy | I6: =-I5*0.1 -> -129600 | J6: =I6*1.03 -> -133488 | K6: =J6*1.03 -> -137492.64 | L6: =K6*1.03 -> -141617.42 | M6: =L6*1.03 -> -145865.94
C7: Income | J7: =I7*1.03 -> 0 | K7: =J7*1.03 -> 0 | L7: =K7*1.03 -> 0 | M7: =L7*1.03 -> 0
C8: Day Care | I8: 2500 | J8: =I8*1.03 -> 2575 | K8: =J8*1.03 -> 2652.25 | L8: =K8*1.03 -> 2731.8175 | M8: =L8*1.03 -> 2813.772
C9: Other Income | I9: 2500 | J9: =I9*1.03 -> 2575 | K9: =J9*1.03 -> 2652.25 | L9: =K9*1.03 -> 2731.8175 | M9: =L9*1.03 -> 2813.772
C10: Rental Income | J10: =I10*1.03 -> 0 | K10: =J10*1.03 -> 0 | L10: =K10*1.03 -> 0 | M10: =L10*1.03 -> 0
C11: Move In Fees | I11: 2500 | J11: =I11*1.03 -> 2575 | K11: =J11*1.03 -> 2652.25 | L11: =K11*1.03 -> 2731.8175 | M11: =L11*1.03 -> 2813.772
C12: Total Income | D12: =SUM(D8:D11) -> 0 | I12: =SUM(I5:I11) -> 1173900 | J12: =I12*1.03 -> 1209117 | K12: =J12*1.03 -> 1245390.5 | L12: =K12*1.03 -> 1282752.2 | M12: =L12*1.03 -> 1321234.8 | O12: =I12*0.05 -> 58695 | P12: =55*4000 -> 220000 | Q12: =P12*12 -> 2640000 | R12: =Q12*0.95 -> 2508000 | S12: =R12*0.05 -> 125400
J13: =I13*1.03 -> 0 | K13: =J13*1.03 -> 0 | L13: =K13*1.03 -> 0 | M13: =L13*1.03 -> 0
C14: Expenses | J14: =I14*1.03 -> 0 | K14: =J14*1.03 -> 0 | L14: =K14*1.03 -> 0 | M14: =L14*1.03 -> 0
C15: Accounting | I15: 3500 | J15: =I15*1.03 -> 3605 | K15: =J15*1.03 -> 3713.15 | L15: =K15*1.03 -> 3824.5445 | M15: =L15*1.03 -> 3939.2808
C16: Advertising/Promotional | I16: 3500 | J16: =I16*1.03 -> 3605 | K16: =J16*1.03 -> 3713.15 | L16: =K16*1.03 -> 3824.5445 | M16: =L16*1.03 -> 3939.2808
C17: Bank Charges | I17: 250 | J17: =I17*1.03 -> 257.5 | K17: =J17*1.03 -> 265.225 | L17: =K17*1.03 -> 273.18175 | M17: =L17*1.03 -> 281.3772
C18: Business licenses/Permits | I18: 2820 | J18: =I18*1.03 -> 2904.6 | K18: =J18*1.03 -> 2991.738 | L18: =K18*1.03 -> 3081.4901 | M18: =L18*1.03 -> 3173.9348
C19: Nursing | I19: 15000 | J19: =I19*1.03 -> 15450 | K19: =J19*1.03 -> 15913.5 | L19: =K19*1.03 -> 16390.905 | M19: =L19*1.03 -> 16882.632
C20: Dietician | J20: =I20*1.03 -> 0 | K20: =J20*1.03 -> 0 | L20: =K20*1.03 -> 0 | M20: =L20*1.03 -> 0
C21: Dues & Subscriptions | I21: 1500 | J21: =I21*1.03 -> 1545 | K21: =J21*1.03 -> 1591.35 | L21: =K21*1.03 -> 1639.0905 | M21: =L21*1.03 -> 1688.2632
C22: Administrator Expense | J22: =I22*1.03 -> 0 | K22: =J22*1.03 -> 0 | L22: =K22*1.03 -> 0 | M22: =L22*1.03 -> 0
C23: Employee Expenses | I23: 500000 | J23: =I23*1.03 -> 515000 | K23: =J23*1.03 -> 530450 | L23: =K23*1.03 -> 546363.5 | M23: =L23*1.03 -> 562754.41
C24: Franchise Fees | J24: =I24*1.03 -> 0 | K24: =J24*1.03 -> 0 | L24: =K24*1.03 -> 0 | M24: =L24*1.03 -> 0 | T24: =10*50000 -> 500000
C25: Cleaning | J25: =I25*1.03 -> 0 | K25: =J25*1.03 -> 0 | L25: =K25*1.03 -> 0 | M25: =L25*1.03 -> 0 | T25: =125000*10 -> 1250000
C26: Household Supplies | I26: 20000 | J26: =I26*1.03 -> 20600 | K26: =J26*1.03 -> 21218 | L26: =K26*1.03 -> 21854.54 | M26: =L26*1.03 -> 22510.176
C27: Management Fees | J27: =I27*1.03 -> 0 | K27: =J27*1.03 -> 0 | L27: =K27*1.03 -> 0 | M27: =L27*1.03 -> 0
C28: General business expenses | I28: 1500 | J28: =I28*1.03 -> 1545 | K28: =J28*1.03 -> 1591.35 | L28: =K28*1.03 -> 1639.0905 | M28: =L28*1.03 -> 1688.2632
C29: Insurance | I29: 15000 | J29: =I29*1.03 -> 15450 | K29: =J29*1.03 -> 15913.5 | L29: =K29*1.03 -> 16390.905 | M29: =L29*1.03 -> 16882.632
C30: Liability insurance | J30: =I30*1.03 -> 0 | K30: =J30*1.03 -> 0 | L30: =K30*1.03 -> 0 | M30: =L30*1.03 -> 0
C31: Property insurance | J31: =I31*1.03 -> 0 | K31: =J31*1.03 -> 0 | L31: =K31*1.03 -> 0 | M31: =L31*1.03 -> 0
C32: Lease Payments - Equipment | I32: 2400 | J32: =I32*1.03 -> 2472 | K32: =J32*1.03 -> 2546.16 | L32: =K32*1.03 -> 2622.5448 | M32: =L32*1.03 -> 2701.2211
C33: Medical Supplies | I33: 13000 | J33: =I33*1.03 -> 13390 | K33: =J33*1.03 -> 13791.7 | L33: =K33*1.03 -> 14205.451 | M33: =L33*1.03 -> 14631.615
C34: Office expenses | I34: 2500 | J34: =I34*1.03 -> 2575 | K34: =J34*1.03 -> 2652.25 | L34: =K34*1.03 -> 2731.8175 | M34: =L34*1.03 -> 2813.772
C35: Operations Contract Service | J35: =I35*1.03 -> 0 | K35: =J35*1.03 -> 0 | L35: =K35*1.03 -> 0 | M35: =L35*1.03 -> 0
C36: Placement Fees | I36: 15000 | J36: =I36*1.03 -> 15450 | K36: =J36*1.03 -> 15913.5 | L36: =K36*1.03 -> 16390.905 | M36: =L36*1.03 -> 16882.632
C37: Raw Food | I37: 70000 | J37: =I37*1.03 -> 72100 | K37: =J37*1.03 -> 74263 | L37: =K37*1.03 -> 76490.89 | M37: =L37*1.03 -> 78785.617
C38: Repairs & maintenance | I38: 15000 | J38: =I38*1.03 -> 15450 | K38: =J38*1.03 -> 15913.5 | L38: =K38*1.03 -> 16390.905 | M38: =L38*1.03 -> 16882.632
C39: Resident Activities | I39: 2500 | J39: =I39*1.03 -> 2575 | K39: =J39*1.03 -> 2652.25 | L39: =K39*1.03 -> 2731.8175 | M39: =L39*1.03 -> 2813.772
C40: Taxes paid | J40: =I40*1.03 -> 0 | K40: =J40*1.03 -> 0 | L40: =K40*1.03 -> 0 | M40: =L40*1.03 -> 0
C41: Property taxes | I41: 12000 | J41: =I41*1.03 -> 12360 | K41: =J41*1.03 -> 12730.8 | L41: =K41*1.03 -> 13112.724 | M41: =L41*1.03 -> 13506.106
C42: Personal Property Taxes | J42: =I42*1.03 -> 0 | K42: =J42*1.03 -> 0 | L42: =K42*1.03 -> 0 | M42: =L42*1.03 -> 0
...

Sheet Bank Proforma
C2: 3 Year Historicals (Actuals)
C4: Year | D4: 2022 | E4: 2023 | F4: 2024 | G4: 2025 YTD (march) | H4: 2025 Annualized | I4: Proforma Year 1 | J4: Proforma Year 2 | K4: Proforma Year 3 | L4: Proforma Year 4 | M4: Proforma Year 5
C5: Potential Income | I5: =5000*20*12 -> 1200000 | J5: =I5*1.03 -> 1236000 | K5: =J5*1.03 -> 1273080 | L5: =K5*1.03 -> 1311272.4 | M5: =L5*1.03 -> 1350610.6
C6: Vacancy | I6: =-I5*0.08 -> -96000 | J6: =-J5*0.08 -> -98880 | K6: =-K5*0.08 -> -101846.4 | L6: =-L5*0.08 -> -104901.79 | M6: =-M5*0.08 -> -108048.85
C7: Income
C8: Day Care | I8: 5000 | J8: =I8*1.2 -> 6000 | K8: =J8*1.2 -> 7200 | L8: =K8*1.2 -> 8640 | M8: =L8*1.2 -> 10368
C9: Other Income | I9: 2500 | J9: =I9 -> 2500 | K9: =J9 -> 2500 | L9: =K9 -> 2500 | M9: =L9 -> 2500
C10: Rental Income | D10: 762385.9 | E10: 898360.99 | F10: 982748.03 | G10: 229323.19 | H10: =G10*4 -> 917292.76 | I10: =I5+I6 -> 1104000 | J10: =J5+J6 -> 1137120 | K10: =K5+K6 -> 1171233.6 | L10: =L5+L6 -> 1206370.6 | M10: =M5+M6 -> 1242561.7
C11: Move In Fees | I11: 5000 | J11: =I11*1.2 -> 6000 | K11: =J11*1.2 -> 7200 | L11: =K11*1.2 -> 8640 | M11: =L11*1.2 -> 10368
C12: Total Income | D12: =SUM(D8:D11) -> 762385.9 | E12: =SUM(E8:E11) -> 898360.99 | F12: =SUM(F8:F11) -> 982748.03 | G12: =SUM(G8:G11) -> 229323.19 | H12: =SUM(H8:H11) -> 917292.76 | I12: =SUM(I8:I11) -> 1116500 | J12: =SUM(J8:J11) -> 1151620 | K12: =SUM(K8:K11) -> 1188133.6 | ... M12: =SUM(M8:M11) -> 1265797.7
C14: Expenses
C15: Accounting | D15: $ - | E15: 1200 | F15: 11028.5 | G15: 1755 | H15: =G15*4 -> 7020 | I15: 8000 | J15: =I15*1.03 -> 8240 | K15: =J15*1.03 -> 8487.2 | L15: =K15*1.03 -> 8741.816 | M15: =L15*1.03 -> 9004.0705
C16: Advertising/Promotional | D16: 5965.18 | E16: 1525.14 | F16: 6522.48 | G16: 606.38 | H16: =G16*4 -> 2425.52 | I16: 6500 | J16: =I16*1.03 -> 6695 | K16: =J16*1.03 -> 6895.85 | L16: =K16*1.03 -> 7102.7255 | M16: =L16*1.03 -> 7315.8073
C17: Bank Charges | D17: 2 | E17: 1455.2 | F17: 1158.92 | G17: 75 | H17: =G17*4 -> 300 | I17: 1200 | J17: =I17*1.03 -> 1236 | K17: =J17*1.03 -> 1273.08 | L17: =K17*1.03 -> 1311.2724 | M17: =L17*1.03 -> 1350.6106
C18: Business licenses/Permits | D18: 2317 | E18: 2689 | F18: 829 | H18: =G18*4 -> 0 | I18: 2500 | J18: =I18*1.03 -> 2575 | K18: =J18*1.03 -> 2652.25 | L18: =K18*1.03 -> 2731.8175 | M18: =L18*1.03 -> 2813.772
C19: Nursing | D19: 3067.5 | E19: 3745 | F19: 4617.5 | G19: 957.5 | H19: =G19*4 -> 3830 | I19: 4500 | J19: =I19*1.03 -> 4635 | K19: =J19*1.03 -> 4774.05 | L19: =K19*1.03 -> 4917.2715 | M19: =L19*1.03 -> 5064.7896
C20: Dietician | H20: =G20*4 -> 0 | J20: =I20*1.03 -> 0 | K20: =J20*1.03 -> 0 | L20: =K20*1.03 -> 0 | M20: =L20*1.03 -> 0
C21: Dues & Subscriptions | D21: 1918.81 | E21: 1699.73 | F21: 5171.09 | G21: 1305.48 | H21: =G21*4 -> 5221.92 | I21: 2500 | J21: =I21*1.03 -> 2575 | K21: =J21*1.03 -> 2652.25 | L21: =K21*1.03 -> 2731.8175 | M21: =L21*1.03 -> 2813.772
C22: Administrator Expense | D22: 65000 | E22: 65000 | F22: 65000 | G22: =65000/4 -> 16250 | H22: =G22*4 -> 65000 | I22: 65000 | J22: =I22*1.03 -> 66950 | K22: =J22*1.03 -> 68958.5 | L22: =K22*1.03 -> 71027.255 | M22: =L22*1.03 -> 73158.073
C23: Employee Expenses | D23: =372150.03-D22+2021.49+179 -> 309350.52 | E23: =516817.64-E22+752.07+1162.79 -> 453732.5 | F23: =543985.31-F22+1707.34+100 -> 480792.65 | G23: =133613.48-G22+98.35 -> 117461.83 | H23: =G23*4 -> 469847.32 | I23: 450000 | J23: =I23*1.03 -> 463500 | K23: =J23*1.03 -> 477405 | L23: =K23*1.03 -> 491727.15 | M23: =L23*1.03 -> 506478.96
C24: Franchise Fees | H24: =G24*4 -> 0 | I24: 0 | J24: =I24*1.03 -> 0 | K24: =J24*1.03 -> 0 | L24: =K24*1.03 -> 0 | M24: =L24*1.03 -> 0
C25: Cleaning | H25: =G25*4 -> 0 | I25: 0 | J25: =I25*1.03 -> 0 | K25: =J25*1.03 -> 0 | L25: =K25*1.03 -> 0 | M25: =L25*1.03 -> 0
C26: Household Supplies | D26: =8223.22+10820.73 -> 19043.95 | E26: =4866.29-13.35 -> 4852.94 | F26: =3711.27+1099.43 -> 4810.7 | G26: =699.96+277.55 -> 977.51 | H26: =G26*4 -> 3910.04 | I26: 5000 | J26: =I26*1.03 -> 5150 | K26: =J26*1.03 -> 5304.5 | L26: =K26*1.03 -> 5463.635 | M26: =L26*1.03 -> 5627.5441
C27: Management Fees | H27: =G27*4 -> 0 | I27: 0 | J27: =I27*1.03 -> 0 | K27: =J27*1.03 -> 0 | L27: =K27*1.03 -> 0 | M27: =L27*1.03 -> 0
C28: General business expenses | H28: =G28*4 -> 0 | I28: 0 | J28: =I28*1.03 -> 0 | K28: =J28*1.03 -> 0 | L28: =K28*1.03 -> 0 | M28: =L28*1.03 -> 0
C29: Insurance | D29: 1389.84 | E29: $ - | F29: 21949.61 | G29: 327 | H29: =G29*4 -> 1308 | I29: 21949.61 | J29: =I29*1.03 -> 22608.098 | K29: =J29*1.03 -> 23286.341 | L29: =K29*1.03 -> 23984.931 | M29: =L29*1.03 -> 24704.479
C30: Liability insurance | H30: =G30*4 -> 0 | J30: =I30*1.03 -> 0 | K30: =J30*1.03 -> 0 | L30: =K30*1.03 -> 0 | M30: =L30*1.03 -> 0
C31: Property insurance | H31: =G31*4 -> 0 | J31: =I31*1.03 -> 0 | K31: =J31*1.03 -> 0 | L31: =K31*1.03 -> 0 | M31: =L31*1.03 -> 0
C32: Lease Payments - Equipment | D32: 200 | F32: 783.82 | G32: 98.2 | H32: =G32*4 -> 392.8 | I32: 785 | J32: =I32*1.03 -> 808.55 | K32: =J32*1.03 -> 832.8065 | L32: =K32*1.03 -> 857.7907 | M32: =L32*1.03 -> 883.52442
C33: Medical Supplies | D33: 6602.89 | E33: 3349.16 | F33: 4064.08 | G33: 759.82 | H33: =G33*4 -> 3039.28 | I33: 4500 | J33: =I33*1.03 -> 4635 | K33: =J33*1.03 -> 4774.05 | L33: =K33*1.03 -> 4917.2715 | M33: =L33*1.03 -> 5064.7896
C34: Office expenses | D34: =43.3+950.68 -> 993.98 | E34: =161.88+27.49+659.21 -> 848.58 | F34: =744.4+99.66+25.86 -> 869.92 | G34: =1060.03+12.25+97.12 -> 1169.4 | H34: =G34*4 -> 4677.6 | I34: 1000 | J34: =I34*1.03 -> 1030 | K34: =J34*1.03 -> 1060.9 | L34: =K34*1.03 -> 1092.727 | M34: =L34*1.03 -> 1125.5088
C35: Operations Contract Service | D35: 1206.29 | E35: 1308 | F35: 1309.9 | G35: 426.2 | H35: =G35*4 -> 1704.8 | I35: 1500 | J35: =I35*1.03 -> 1545 | K35: =J35*1.03 -> 1591.35 | L35: =K35*1.03 -> 1639.0905 | M35: =L35*1.03 -> 1688.2632
C36: Placement Fees | H36: =G36*4 -> 0 | J36: =I36*1.03 -> 0 | K36: =J36*1.03 -> 0 | L36: =K36*1.03 -> 0 | M36: =L36*1.03 -> 0
C37: Raw Food | D37: 35749.36 | E37: 40486.08 | F37: 36303.32 | G37: 8753.37 | H37: =G37*4 -> 35013.48 | I37: 40000 | J37: =I37*1.03 -> 41200 | K37: =J37*1.03 -> 42436 | L37: =K37*1.03 -> 43709.08 | M37: =L37*1.03 -> 45020.352
C38: Repairs & maintenance | D38: 19962.91 | E38: =1110.41+8499.21 -> 9609.62 | F38: =1029.82+12540.51 -> 13570.33 | G38: =1196.79+1240.18 -> 2436.97 | H38: =G38*4 -> 9747.88 | I38: 15000 | J38: =I38*1.03 -> 15450 | K38: =J38*1.03 -> 15913.5 | L38: =K38*1.03 -> 16390.905 | M38: =L38*1.03 -> 16882.632
C39: Resident Activities | D39: 520.38 | E39: 903.39 | F39: 945.64 | G39: 169 | H39: =G39*4 -> 676 | I39: 2500 | J39: =I39*1.03 -> 2575 | K39: =J39*1.03 -> 2652.25 | L39: =K39*1.03 -> 2731.8175 | M39: =L39*1.03 -> 2813.772
C40: Taxes paid | D40: 830.29 | E40: 25122.8 | F40: 9.7 | H40: =G40*4 -> 0 | I40: 9711.18 | J40: =I40*1.03 -> 10002.515 | K40: =J40*1.03 -> 10302.591 | L40: =K40*1.03 -> 10611.669 | M40: =L40*1.03 -> 10930.019
C41: Property taxes | H41: =G41*4 -> 0 | J41: =I41*1.03 -> 0 | K41: =J41*1.03 -> 0 | L41: =K41*1.03 -> 0 | M41: =L41*1.03 -> 0
C42: Personal Property Taxes | H42: =G42*4 -> 0
C43: Travel/Vehicle | H43: =G43*4 -> 0 | J43: =I43*1.03 -> 0 | K43: =J43*1.03 -> 0 | L43: =K43*1.03 -> 0 | M43: =L43*1.03 -> 0
...

Sheet 3 Year Proforma
C2: Proforma | J2: Actuals
D4: Year 1 | E4: Year 2 | F4: Year 3 | G4: Year 4 | H4: Year 5 | K4: =Proforma!D4 -> 2022 | L4: =Proforma!E4 -> 2023 | M4: =Proforma!F4 -> 2024 | N4: =Proforma!G4 -> 2025 YTD (Sept) | O4: =Proforma!H4 -> 2025
C5: Gross Potential Rent | D5: =166554.6*12 -> 1998655.2 | E5: =D5*1.03 -> 2058614.9 | F5: =E5*1.03 -> 2120373.3
C6: Vacancy @ 5% | D6: =D5*-0.086 -> -171884.35 | E6: =E5*-0.086 -> -177040.88 | F6: =F5*-0.086 -> -182352.1
C7: Other Income | D7: =2842.28*12 -> 34107.36 | E7: =2842.28*12 -> 34107.36 | F7: =2842.28*12 -> 34107.36
C8: Effective Gross Income | D8: =Proforma!I12 -> 1627500 | E8: =Proforma!J12 -> 1676325 | F8: =Proforma!K12 -> 1726614.8 | G8: =Proforma!L12 -> 1778413.2 | H8: =Proforma!M12 -> 1831765.6 | J8: =C8 -> Effective Gross Income | K8: =Proforma!D12 -> 0 | L8: =Proforma!E12 -> 1515350.4 | M8: =Proforma!F12 -> 1454220.4 | N8: =Proforma!G12 -> 1173653.1 | O8: =Proforma!H12 -> 1591068.2
C9: Expenses | D9: =Proforma!I46 -> 1095845 | E9: =Proforma!J46 -> 1128720.4 | F9: =Proforma!K46 -> 1162582 | G9: =Proforma!L46 -> 1197459.4 | H9: =Proforma!M46 -> 1233383.2 | J9: =C9 -> Expenses | K9: =Proforma!D46 -> 0 | L9: =Proforma!E46 -> 1236849.2 | M9: =Proforma!F46 -> 1142114.2 | N9: =Proforma!G46 -> 917971.87 | O9: =Proforma!H46 -> 1264735.3
C11: Net Operating Income | D11: =D8-D9 -> 531655 | E11: =E8-E9 -> 547604.65 | F11: =F8-F9 -> 564032.79 | G11: =G8-G9 -> 580953.77 | H11: =H8-H9 -> 598382.39 | J11: =C11 -> Net Operating Income | K11: =K8-K9 -> 0 | L11: =L8-L9 -> 278501.2 | M11: =M8-M9 -> 312106.18 | N11: =N8-N9 -> 255681.26 | O11: =O8-O9 -> 326332.86
J13: Excluded Expenses
J14: Owner HSA
J15: Owner Life Insurance
J16: Owner Salary
J17: Owner Vehicle
J18: Owner Storage Unit
J19: Owner Short Term Interst
J20: Owner Other Income
J21: Owner Mortgage Payment

Sheet Reimbursements
D1: Check | E1: Deposited to
A2: Earnest Money | B2: Cory 1031 Money
A3: Apprisal
A4: Inspection
A5: Environmental

Sheet Capital Stack
A1: Investor | B1: Amount | C1: Name/Entity | D1: Final Ownership | E1: Ownership | F1: Email | G1: Identifier | H1: Signed Docs | I1: Wire | J1: Both
D2: =E2*0.1 -> #DIV/0! | E2: =B2/$B$15 -> #DIV/0!
D3: =E3*0.1 -> #DIV/0! | E3: =B3/$B$15 -> #DIV/0!
D4: =E4*0.1 -> #DIV/0! | E4: =B4/$B$15 -> #DIV/0!
D5: =E5*0.1 -> #DIV/0! | E5: =B5/$B$15 -> #DIV/0!
D6: =E6*0.1 -> #DIV/0! | E6: =B6/$B$15 -> #DIV/0!
D7: =E7*0.1 -> #DIV/0! | E7: =B7/$B$15 -> #DIV/0!
D8: =E8*0.1 -> #DIV/0! | E8: =B8/$B$15 -> #DIV/0!
D9: =E9*0.1 -> #DIV/0! | E9: =B9/$B$15 -> #DIV/0!
D10: =E10*0.1 -> #DIV/0! | E10: =B10/$B$15 -> #DIV/0!
D11: =E11*0.1 -> #DIV/0! | E11: =B11/$B$15 -> #DIV/0!
D12: =E12*0.1 -> #DIV/0! | E12: =B12/$B$15 -> #DIV/0!
D13: 0.45
D14: 0.45
A15: Total | B15: =SUM(B2:B14) -> 0
A16: Remaining
A19: Reached out | C19: Followed up.
A20: Cam Cope | B20: Maybe | C20: 45222
A23: Bryan Griffiths | B23: Maybe | C23: 45222
A24: Alex Smith | B24: Maybe
A25: Randy Clayton
A27: Ben Clayton
A28: Jeff Meihoffer
A29: Rich Toloti | B29: Maybe
A30: Woody Klemetson
A31: Sterling Snow
A32: Blakely Cragun
A33: Adam and Andrew Law
A34: Ray Dodd
A35: Todd Orullian
A36: Adam Christensen
A37: Matt Boardman
A38: Scott Eliason
A39: Devin Deaton | B39: No
A40: Cameron Lee | B40: No
A41: Eric Motzkus | B41: No
A42: Aaron Meier | B42: No
A43: Mike Peterson | B43: No
A44: Jon Waddoups | B44: No
A45: Joel Reichert | B45: No
...
