Workbook

Sheet Deal Overview
B2: Deal Summary | F2: Sensitivity Analysis
B4: Cost Summary | C4: Cost | F4: Scenarios >>> | G4: Disappointed | H4: Conservative | I4: Expected | J4: Aggressive
B5: Purchase Price | C5: ='Sources and Uses'!D5 -> 2050000 | F5: Gross Potential Rent | G5: =H5 -> 960000 | H5: =I5 -> 960000 | I5: =Proforma!I5 -> 960000 | J5: =I5 -> 960000
B6: ='Sources and Uses'!B9 -> Total Debt | C6: ='Sources and Uses'!D9 -> 1640000 | F6: Vacancy | G6: =H6*1.05 -> -105840 | H6: =I6*1.05 -> -100800 | I6: =Proforma!I6 -> -96000 | J6: =-J5*0.1 -> -96000
B7: Total Fees | C7: ='Sources and Uses'!D23 -> 159900 | F7: Other Income
B8: Total Equity | C8: ='Sources and Uses'!G20 -> 590400 | F8: Effective Gross Income | G8: =G7+G6+G5 -> 854160 | H8: =H7+H6+H5 -> 859200 | I8: =Proforma!I12 -> 876500 | J8: =J7+J6+J5 -> 864000
B9: Reserve | C9: ='Sources and Uses'!G19 -> 20500 | F9: Expenses | G9: =H9 -> 631670 | H9: =I9 -> 631670 | I9: =Proforma!I46 -> 631670 | J9: =I9*0.9 -> 568503
B10: Total Cost | C10: =C5+C7+C9 -> 2230400 | F10: Management Fees 3rd Party | G10: =H10 -> 35060 | H10: =I10 -> 35060 | I10: =Proforma!I54 -> 35060 | J10: =I10 -> 35060
F11: Vega Asset Management Fees | G11: =H11 -> 8765 | H11: =I11 -> 8765 | I11: =Proforma!I53 -> 8765 | J11: =I11 -> 8765
B12: Total | C12: $ | D12: % | F12: Misc Unexpected Expense Reserve | G12: =H12 -> 8765 | H12: =I12 -> 8765 | I12: =Proforma!I51 -> 8765 | J12: =I12 -> 8765
B13: Equity | C13: =C8 -> 590400 | D13: =C13/C15 -> 0.26470588 | F13: Net Operating Income | G13: =G8-G9-G10-G11-G12 -> 169900 | H13: =H8-H9-H10-H11-H12 -> 174940 | I13: =I8-I9-I10-I11-I12 -> 192240 | J13: =J8-J9-J10-J11-J12 -> 242907
B14: Debt | C14: =C6 -> 1640000 | D14: =C14/C15 -> 0.73529412
B15: Total Required Capital From All Sources | C15: =C14+C13 -> 2230400 | D15: =SUM(D13:D14) -> 1 | F15: Annual Payment | G15: ='Sources and Uses'!$J$9 -> 132796.38 | H15: ='Sources and Uses'!$J$9 -> 132796.38 | I15: ='Sources and Uses'!$J$9 -> 132796.38 | J15: ='Sources and Uses'!$J$9 -> 132796.38
F16: Cash Flow | G16: =G13-G15 -> 37103.619 | H16: =H13-H15 -> 42143.619 | I16: =I13-I15 -> 59443.619 | J16: =J13-J15 -> 110110.62
B17: Total | D17: % | F17: Investor Pref | G17: =H17 -> 47232 | H17: =I17 -> 47232 | I17: =D18*'Sources and Uses'!D13 -> 47232 | J17: =I17 -> 47232
B18: Investor Pref | D18: 0.08 | F18: Remaining | G18: =if((G16-G17)>0,G16-G17,"") | H18: =if((H16-H17)>0,H16-H17,"") | I18: =if((I16-I17)>0,I16-I17,"") -> 12211.619 | J18: =if((J16-J17)>0,J16-J17,"") -> 62878.619
B19: Sponsor Promote | C19: =C11 | D19: 0.5 | F19: Investor Split | G19: =G18/2 -> 0 | H19: =H18/2 -> 0 | I19: =I18/2 -> 6105.8094 | J19: =J18/2 -> 31439.309
F20: Sponsor Split | G20: =G19 -> 0 | H20: =H19 -> 0 | I20: =I19 -> 6105.8094 | J20: =J19 -> 31439.309
F21: Total Investor Cash Flow Upon Stabilization | G21: =if((G16-G17)>0,G19+G17,G16) -> 37103.619 | H21: =if((H16-H17)>0,H19+H17,H16) -> 42143.619 | I21: =if((I16-I17)>0,I19+I17,I16) -> 53337.809 | J21: =if((J16-J17)>0,J19+J17,J16) -> 78671.309
F22: 1st Year Cash on Cash | G22: =G21/'Sources and Uses'!$D$13 -> 0.062844883 | H22: =H21/'Sources and Uses'!$D$13 -> 0.071381468 | I22: =I21/'Sources and Uses'!$D$13 -> 0.090341818 | J22: =J21/'Sources and Uses'!$D$13 -> 0.13325086
F23: 1st Year Principal Reduction | G23: =H23 -> 0.045769376 | H23: =I23 -> 0.045769376 | I23: =-'Sources and Uses'!M8/'Sources and Uses'!D13 -> 0.045769376 | J23: =I23 -> 0.045769376
F24: Total 1st Year benefit | G24: =G23+G22 -> 0.10861426 | H24: =H23+H22 -> 0.11715084 | I24: =I23+I22 -> 0.13611119 | J24: =J23+J22 -> 0.17902024

Sheet Sam Copy of Deal Overview
B2: Deal Summary | F2: Sensitivity Analysis
B4: Cost Summary | C4: Cost | F4: Scenarios >>> | G4: Disappointed | H4: Conservative | I4: Expected | J4: Aggressive
B5: Purchase Price | C5: ='Sources and Uses'!D5 -> 2050000 | F5: Gross Potential Rent | G5: =H5 -> 960000 | H5: =I5 -> 960000 | I5: =Proforma!I5 -> 960000 | J5: =I5 -> 960000
B6: ='Sources and Uses'!B9 -> Total Debt | C6: ='Sources and Uses'!D9 -> 1640000 | F6: Vacancy | G6: =H6*1.05 -> -105840 | H6: =I6*1.05 -> -100800 | I6: =Proforma!I6 -> -96000 | J6: =-J5*0.1 -> -96000
B7: Total Fees | C7: ='Sources and Uses'!D23 -> 159900 | F7: Other Income
B8: Total Equity | C8: ='Sources and Uses'!G20 -> 590400 | F8: Effective Gross Income | G8: =G7+G6+G5 -> 854160 | H8: =H7+H6+H5 -> 859200 | I8: =Proforma!I12 -> 876500 | J8: =J7+J6+J5 -> 864000
B9: Reserve | C9: ='Sources and Uses'!G19 -> 20500 | F9: Expenses | G9: =H9 -> 631670 | H9: =I9 -> 631670 | I9: =Proforma!I46 -> 631670 | J9: =I9*0.9 -> 568503
B10: Total Cost | C10: =C5+C7+C9 -> 2230400 | F10: Management Fees 3rd Party | G10: =H10 -> 35060 | H10: =I10 -> 35060 | I10: =Proforma!I54 -> 35060 | J10: =I10 -> 35060
F11: Vega Asset Management Fees | G11: =H11 -> 8765 | H11: =I11 -> 8765 | I11: =Proforma!I53 -> 8765 | J11: =I11 -> 8765
B12: Total | C12: $ | D12: % | F12: Misc Unexpected Expense Reserve | G12: =H12 -> 8765 | H12: =I12 -> 8765 | I12: =Proforma!I51 -> 8765 | J12: =I12 -> 8765
B13: Equity | C13: =C8 -> 590400 | D13: =C13/C15 -> 0.26470588 | F13: Net Operating Income | G13: =G8-G9-G10-G11-G12 -> 169900 | H13: =H8-H9-H10-H11-H12 -> 174940 | I13: =I8-I9-I10-I11-I12 -> 192240 | J13: =J8-J9-J10-J11-J12 -> 242907
B14: Debt | C14: =C6 -> 1640000 | D14: =C14/C15 -> 0.73529412
B15: Total Required Capital From All Sources | C15: =C14+C13 -> 2230400 | D15: =SUM(D13:D14) -> 1 | F15: Annual Payment | G15: ='Sources and Uses'!$J$9 -> 132796.38 | H15: ='Sources and Uses'!$J$9 -> 132796.38 | I15: ='Sources and Uses'!$J$9 -> 132796.38 | J15: ='Sources and Uses'!$J$9 -> 132796.38
F16: Cash Flow | G16: =G13-G15 -> 37103.619 | H16: =H13-H15 -> 42143.619 | I16: =I13-I15 -> 59443.619 | J16: =J13-J15 -> 110110.62
B17: Total | D17: % | F17: Investor Pref | G17: =H17 -> 47232 | H17: =I17 -> 47232 | I17: =D18*'Sources and Uses'!D13 -> 47232 | J17: =I17 -> 47232
B18: Investor Pref | D18: 0.08 | F18: Remaining | G18: =if((G16-G17)>0,G16-G17,"") | H18: =if((H16-H17)>0,H16-H17,"") | I18: =if((I16-I17)>0,I16-I17,"") -> 12211.619 | J18: =if((J16-J17)>0,J16-J17,"") -> 62878.619
B19: Sponsor Promote | C19: =C11 | D19: 0.5 | F19: Investor Split | G19: =G18/2 -> 0 | H19: =H18/2 -> 0 | I19: =I18/2 -> 6105.8094 | J19: =J18/2 -> 31439.309
F20: Sponsor Split | G20: =G19 -> 0 | H20: =H19 -> 0 | I20: =I19 -> 6105.8094 | J20: =J19 -> 31439.309
F21: Total Investor Cash Flow Upon Stabilization | G21: =if((G16-G17)>0,G19+G17,G16) -> 37103.619 | H21: =if((H16-H17)>0,H19+H17,H16) -> 42143.619 | I21: =if((I16-I17)>0,I19+I17,I16) -> 53337.809 | J21: =if((J16-J17)>0,J19+J17,J16) -> 78671.309
F22: 1st Year Cash on Cash | G22: =G21/'Sources and Uses'!$D$13 -> 0.062844883 | H22: =H21/'Sources and Uses'!$D$13 -> 0.071381468 | I22: =I21/'Sources and Uses'!$D$13 -> 0.090341818 | J22: =J21/'Sources and Uses'!$D$13 -> 0.13325086
F23: 1st Year Principal Reduction | G23: =H23 -> 0.045769376 | H23: =I23 -> 0.045769376 | I23: =-'Sources and Uses'!M8/'Sources and Uses'!D13 -> 0.045769376 | J23: =I23 -> 0.045769376
F24: Total 1st Year benefit | G24: =G23+G22 -> 0.10861426 | H24: =H23+H22 -> 0.11715084 | I24: =I23+I22 -> 0.13611119 | J24: =J23+J22 -> 0.17902024
F27: Target Exit Price (8% Cap Rate) | G27: =Proforma!M47/0.08 -> 3559068.3
F28: Sale Cost at Year 5 | G28: =G27*0.06 -> 213544.1
F29: Loan Balance at Year 5 | G29: =Proforma!M58 -> 1485501.9
F30: Net Proceeds at Sale End of Year 5 | G30: =G27-G28-G29 -> 1860022.3
F31: Profit | G31: =G30-C13 -> 1269622.3
F32: Sponsor Fees | G32: =G31/2 -> 634811.13
F33: Total Investor Benefit | G33: =G32+SUM(Proforma!I64:M64)+-SUM('Sources and Uses'!M8:Q8) -> 1096829.3
F34: Total Investor Return | G34: =G33/C13 -> 1.8577732
F35: Annualized Return | G35: =G34/5 -> 0.37155464
F40: Total Return (3 Properties) | G40: =G33+1531732.18+1554475.18 -> 4183036.6
F41: Total Equity | G41: =C13+626250+1084000 -> 2300650
F42: Total Return (3 Properties) | G42: =G40/G41 -> 1.8181977
F43: Annualized Return | G43: =G42/5 -> 0.36363955
F47: Cash on Cash Yr 1 | G47: =(I21+88373+88685)/(C13+626250+1084000) -> 0.10014379
F48: Cash on Cash Yr 2 | G48: =(Proforma!J64+94347.71+71627.4)/G41 -> 0.096972538
F49: Cash on Cash Yr 3 | G49: =(100667.86+75900.72+Proforma!K64)/G41 -> 0.10334271

Sheet Sources and Uses
B2: Sources and Uses of Funds
B4: Acquisition Assumptions | F4: Lender | G4: Amount | H4: Interest Rate | I4: Term | J4: Monthly Payment | L4: Principal Reduction | M4: Year 1 | N4: Year 2 | O4: Year 3 | P4: Year 4 | Q4: Year 5
B5: Total Project Cost | D5: =2550000-G10 -> 2050000 | F5: 1st Position | G5: =D6 -> 1025000 | H5: 0.06375 | I5: 25 | J5: =PMT(H5/12,I5*12,-G5,0,0) -> 6841.0268 | M5: =iferror(CUMPRINC(H5/12,I5*12,G5,1,12,0),"") -> -17246.714 | N5: =iferror(CUMPRINC(H5/12,I5*12,G5,13,24,0),"") -> -18378.893 | O5: =iferror(CUMPRINC(H5/12,I5*12,G5,25,36,0),"") -> -19585.395 | P5: =iferror(CUMPRINC(H5/12,I5*12,G5,37,48,0),"") -> -20871.1 | Q5: =iferror(CUMPRINC(H5/12,I5*12,G5,49,60,0),"") -> -22241.205
B6: 1st Position Loan (Bank) | C6: 0.5 | D6: =C6*D5 -> 1025000 | F6: 2nd Position | G6: =D7 -> 615000 | H6: 0.0675 | I6: 25 | J6: =PMT(H6/12,I6*12,-G6,0,1) -> 4225.3384 | M6: =iferror(CUMPRINC(H6/12,I6*12,G6,1,12,0),"") -> -9775.5256 | N6: =iferror(CUMPRINC(H6/12,I6*12,G6,13,24,0),"") -> -10456.175 | O6: =iferror(CUMPRINC(H6/12,I6*12,G6,25,36,0),"") -> -11184.217 | P6: =iferror(CUMPRINC(H6/12,I6*12,G6,37,48,0),"") -> -11962.951 | Q6: =iferror(CUMPRINC(H6/12,I6*12,G6,49,60,0),"") -> -12795.907
B7: 2nd Position Loan (SBA) | C7: 0.3 | D7: =C7*D5 -> 615000 | F7: Seller | G7: =D8 -> 0 | H7: 0.05 | I7: 25 | J7: =PMT(H7/12,I7*12,-G7,0,1) -> 0 | M7: =iferror(CUMPRINC(H7/12,I7*12,G7,1,12,0),"") | N7: =iferror(CUMPRINC(H7/12,I7*12,G7,13,24,0),"") | O7: =iferror(CUMPRINC(H7/12,I7*12,G7,25,36,0),"") | P7: =iferror(CUMPRINC(H7/12,I7*12,G7,37,48,0),"") | Q7: =iferror(CUMPRINC(H7/12,I7*12,G7,49,60,0),"")
B8: 3rd Position Seller Finance | C8: 0 | D8: =C8*D5 -> 0 | F8: Total | G8: =G6+G5+G7 -> 1640000 | I8: Monthly Debt Service | J8: =J6+J5+J7 -> 11066.365 | L8: Total Principal Reduction | M8: =sum(M5:M7) -> -27022.239 | N8: =sum(N5:N7) -> -28835.068 | O8: =sum(O5:O7) -> -30769.612 | P8: =sum(P5:P7) -> -32834.051 | Q8: =sum(Q5:Q7) -> -35037.112
B9: Total Debt | D9: =D8+D7+D6 -> 1640000 | I9: Annual Debt Service | J9: =J8*12 -> 132796.38 | L9: Loan Balance | M9: =G8+M8 -> 1612977.8 | N9: =N8+M9 -> 1584142.7 | O9: =O8+N9 -> 1553373.1 | P9: =P8+O9 -> 1520539 | Q9: =Q8+P9 -> 1485501.9
B10: Down Payment | D10: =D5-D6-D7-D8 -> 410000 | F10: Excess Land Value | G10: 500000
B11: Reserve | C11: 0.01 | D11: =D5*C11 -> 20500 | F11: 1st Year Cash on Cash Return | G11: =Proforma!I56 -> 0.10068364
B12: Fees | D12: =D23 -> 159900
B13: Total Equity | D13: =D12+D11+D10 -> 590400
B14: Total Sources and Uses | D14: =D13+D9 -> 2230400
I15: 1st bank rate: | J15: 0.0637
B16: Fees | F16: Sources and Uses of Funds | I16: Loan amount: | J16: 2069280
B17: Bank Fees | C17: 0.025 | D17: =C17*D9 -> 41000 | F17: Bank Required Down Payment | G17: =D10 -> 410000 | I17: Purchase Price | J17: 2550000
B18: Vega Capital Markets Fee | C18: 0.01 | D18: =C18*D9 -> 16400 | F18: Fees | G18: =D23 -> 159900 | I18: SBA Lender Participation | J18: 6467
B19: Acquisition Fee | C19: 0.03 | D19: =C19*D5 -> 61500 | F19: Reserve | G19: =D11 -> 20500
B20: Due Diligence Costs | C20: 0.01 | D20: =C20*D5 -> 20500 | F20: Total | G20: =SUM(G17:G19) -> 590400 | I20: =D19/G20 -> 0.10416667 | J20: =I20/2 -> 0.052083333
B21: Closing Costs | C21: 0.01 | D21: =C21*D5 -> 20500
B23: Total | D23: =SUM(D17:D22) -> 159900 | F23: Vega Riverton AL LLC | G23: =G20*0.865 -> 510696
F24: Summit | G24: =0.0675*G20 -> 39852
F25: Utah | G25: =0.0675*G20 -> 39852 | N25: =Proforma!I12 -> 876500
G26: =G25+G24+G23 -> 590400
F28: New Building
F29: Land Cost | G29: =G10 -> 500000
F30: Building Cost | G30: 2500000 | H30: =G30/G33 -> 275.45174
F31: Soft Costs | G31: =(G30+G29)*0.1 -> 300000
B32: 292602.49 | F32: Total | G32: =SUM(G29:G31) -> 3300000 | I32: =G32*0.75 -> 2475000
B33: 104000 | F33: Square Feet of New Building | G33: 9076
B34: 104000 | F34: Estimated Net Income of New Building | G34: 300000
B35: =sum(B32:B34) -> 500602.49 | F35: Cap | G35: 0.08
F36: Value of New Building | G36: =G34/G35 -> 3750000
F37: Profit | G37: =G36-G32 -> 450000
F38: Equity | G38: =G36*0.15 -> 562500
L41: All In
L42: Existing Building | M42: =D5 -> 2050000
L43: Excess Land | M43: =G10 -> 500000
L44: New Building | M44: =G32 -> 3300000
L45: Total | M45: =M44+M43+M42 -> 5850000
L47: Total Stabilized NOI | M47: 600000
...

Sheet Proforma
C2: 3 Year Historicals (Actuals)
C4: Year | D4: 2022 | E4: 2023 | F4: 2024 | G4: 2025 YTD (march) | H4: 2025 Annualized | I4: Proforma Year 1 | J4: Proforma Year 2 | K4: Proforma Year 3 | L4: Proforma Year 4 | M4: Proforma Year 5 | O4: Proforma Year 1 | P4: Year 1 Month 1 | Q4: Year 1 Month 2 | R4: Year 1 Month 3 | S4: Year 1 Month 4 | T4: Year 1 Month 5 | U4: Year 1 Month 6 | V4: Year 1 Month 7 | W4: Year 1 Month 8 | X4: Year 1 Month 9 | Y4: Year 1 Month 10 | Z4: Year 1 Month 11 | AA4: Year 1 Month 12 | AB4: Proforma Year 2
C5: Potential Income | I5: 960000 | O5: 960000 | P5: =O5/12 -> 80000 | Q5: =P5 -> 80000 | R5: =Q5 -> 80000 | S5: =R5 -> 80000 | T5: =S5 -> 80000 | U5: =T5 -> 80000 | V5: =U5 -> 80000 | W5: =V5 -> 80000 | X5: =W5 -> 80000 | ... AA5: =Z5 -> 80000 | AB5: =O5*1.05 -> 1008000
C6: Vacancy | I6: =I5*-0.1 -> -96000 | O6: =O5*-0.08 -> -76800 | P6: =O6/12 -> -6400 | Q6: =P6 -> -6400 | R6: =Q6 -> -6400 | S6: =R6 -> -6400 | T6: =S6 -> -6400 | U6: =T6 -> -6400 | V6: =U6 -> -6400 | W6: =V6 -> -6400 | X6: =W6 -> -6400 | ... AA6: =Z6 -> -6400 | AB6: =AB12-AB5 -> -83804
C7: Income
C8: Day Care | I8: 5000 | J8: =I8*1.2 -> 6000 | K8: =J8*1.2 -> 7200 | L8: =K8*1.2 -> 8640 | M8: =L8*1.2 -> 10368 | O8: 5000 | P8: =O8/12 -> 416.66667 | Q8: =P8 -> 416.66667 | R8: =Q8 -> 416.66667 | S8: =R8 -> 416.66667 | T8: =S8 -> 416.66667 | U8: =T8 -> 416.66667 | V8: =U8 -> 416.66667 | W8: =V8 -> 416.66667 | X8: =W8 -> 416.66667 | ... AA8: =Z8 -> 416.66667 | AB8: =O8*1.2 -> 6000
C9: Other Income | F9: 13087.72 | I9: 2500 | J9: =I9 -> 2500 | K9: =J9 -> 2500 | L9: =K9 -> 2500 | M9: =L9 -> 2500 | O9: 2500 | P9: =O9/12 -> 208.33333 | Q9: =P9 -> 208.33333 | R9: =Q9 -> 208.33333 | S9: =R9 -> 208.33333 | T9: =S9 -> 208.33333 | U9: =T9 -> 208.33333 | V9: =U9 -> 208.33333 | W9: =V9 -> 208.33333 | X9: =W9 -> 208.33333 | ... AA9: =Z9 -> 208.33333 | AB9: =O9 -> 2500
C10: Rental Income | F10: 835117.5 | H10: =G10*4 -> 0 | I10: =I5+I6 -> 864000 | J10: =I10*1.03 -> 889920 | K10: =J10*1.03 -> 916617.6 | L10: =K10*1.03 -> 944116.13 | M10: =L10*1.03 -> 972439.61 | N10: =I10/12 -> 72000 | O10: =O5+O6 -> 883200 | P10: =O10/12 -> 73600 | Q10: =P10 -> 73600 | R10: =Q10 -> 73600 | S10: =R10 -> 73600 | T10: =S10 -> 73600 | U10: =T10 -> 73600 | V10: =U10 -> 73600 | W10: =V10 -> 73600 | X10: =W10 -> 73600 | ... AA10: =Z10 -> 73600 | AB10: =O10*1.03 -> 909696
C11: Move In Fees | I11: 5000 | J11: =I11*1.2 -> 6000 | K11: =J11*1.2 -> 7200 | L11: =K11*1.2 -> 8640 | M11: =L11*1.2 -> 10368 | N11: =I11/12 -> 416.66667 | O11: 5000 | P11: =O11/12 -> 416.66667 | Q11: =P11 -> 416.66667 | R11: =Q11 -> 416.66667 | S11: =R11 -> 416.66667 | T11: =S11 -> 416.66667 | U11: =T11 -> 416.66667 | V11: =U11 -> 416.66667 | W11: =V11 -> 416.66667 | X11: =W11 -> 416.66667 | ... AA11: =Z11 -> 416.66667 | AB11: =O11*1.2 -> 6000
C12: Total Income | D12: =SUM(D8:D11) -> 0 | E12: =SUM(E8:E11) -> 0 | F12: =SUM(F8:F11) -> 848205.22 | G12: =SUM(G8:G11) -> 0 | H12: =SUM(H8:H11) -> 0 | I12: =SUM(I8:I11) -> 876500 | J12: =SUM(J8:J11) -> 904420 | K12: =SUM(K8:K11) -> 933517.6 | ... M12: =SUM(M8:M11) -> 995675.61 | N12: =I12/12 -> 73041.667 | O12: =SUM(O8:O11) -> 895700 | P12: =O12/12 -> 74641.667 | Q12: =P12 -> 74641.667 | R12: =Q12 -> 74641.667 | S12: =R12 -> 74641.667 | T12: =S12 -> 74641.667 | U12: =T12 -> 74641.667 | V12: =U12 -> 74641.667 | W12: =V12 -> 74641.667 | X12: =W12 -> 74641.667 | ... AA12: =Z12 -> 74641.667 | AB12: =SUM(AB8:AB11) -> 924196
C14: Expenses
C15: Accounting | F15: 8954.54 | H15: =G15*4 -> 0 | I15: 2000 | J15: =I15*1.03 -> 2060 | K15: =J15*1.03 -> 2121.8 | L15: =K15*1.03 -> 2185.454 | M15: =L15*1.03 -> 2251.0176 | O15: 2000 | P15: =O15/12 -> 166.66667 | Q15: =P15 -> 166.66667 | R15: =Q15 -> 166.66667 | S15: =R15 -> 166.66667 | T15: =S15 -> 166.66667 | U15: =T15 -> 166.66667 | V15: =U15 -> 166.66667 | W15: =V15 -> 166.66667 | X15: =W15 -> 166.66667 | ... AA15: =Z15 -> 166.66667 | AB15: =O15*1.03 -> 2060
C16: Advertising/Promotional | F16: 252.13 | H16: =G16*4 -> 0 | I16: 600 | J16: =I16*1.03 -> 618 | K16: =J16*1.03 -> 636.54 | L16: =K16*1.03 -> 655.6362 | M16: =L16*1.03 -> 675.30529 | O16: 600 | P16: =O16/12 -> 50 | Q16: =P16 -> 50 | R16: =Q16 -> 50 | S16: =R16 -> 50 | T16: =S16 -> 50 | U16: =T16 -> 50 | V16: =U16 -> 50 | W16: =V16 -> 50 | X16: =W16 -> 50 | ... AA16: =Z16 -> 50 | AB16: =O16*1.03 -> 618
C17: Bank Charges | F17: 3817.98 | H17: =G17*4 -> 0 | I17: 500 | J17: =I17*1.03 -> 515 | K17: =J17*1.03 -> 530.45 | L17: =K17*1.03 -> 546.3635 | M17: =L17*1.03 -> 562.75441 | O17: 500 | P17: =O17/12 -> 41.666667 | Q17: =P17 -> 41.666667 | R17: =Q17 -> 41.666667 | S17: =R17 -> 41.666667 | T17: =S17 -> 41.666667 | U17: =T17 -> 41.666667 | V17: =U17 -> 41.666667 | W17: =V17 -> 41.666667 | X17: =W17 -> 41.666667 | ... AA17: =Z17 -> 41.666667 | AB17: =O17*1.03 -> 515
C18: Business licenses/Permits | F18: 1819.25 | H18: =G18*4 -> 0 | I18: 1800 | J18: =I18*1.03 -> 1854 | K18: =J18*1.03 -> 1909.62 | L18: =K18*1.03 -> 1966.9086 | M18: =L18*1.03 -> 2025.9159 | O18: 1800 | P18: =O18/12 -> 150 | Q18: =P18 -> 150 | R18: =Q18 -> 150 | S18: =R18 -> 150 | T18: =S18 -> 150 | U18: =T18 -> 150 | V18: =U18 -> 150 | W18: =V18 -> 150 | X18: =W18 -> 150 | ... AA18: =Z18 -> 150 | AB18: =O18*1.03 -> 1854
C19: Nursing | H19: =G19*4 -> 0 | I19: 6720 | J19: =I19*1.03 -> 6921.6 | K19: =J19*1.03 -> 7129.248 | L19: =K19*1.03 -> 7343.1254 | M19: =L19*1.03 -> 7563.4192 | O19: 6720 | P19: =O19/12 -> 560 | Q19: =P19 -> 560 | R19: =Q19 -> 560 | S19: =R19 -> 560 | T19: =S19 -> 560 | U19: =T19 -> 560 | V19: =U19 -> 560 | W19: =V19 -> 560 | X19: =W19 -> 560 | ... AA19: =Z19 -> 560 | AB19: =O19*1.03 -> 6921.6
C20: Dietician | H20: =G20*4 -> 0 | J20: =I20*1.03 -> 0 | K20: =J20*1.03 -> 0 | L20: =K20*1.03 -> 0 | M20: =L20*1.03 -> 0 | P20: =O20/12 -> 0 | Q20: =P20 -> 0 | R20: =Q20 -> 0 | S20: =R20 -> 0 | T20: =S20 -> 0 | U20: =T20 -> 0 | V20: =U20 -> 0 | W20: =V20 -> 0 | X20: =W20 -> 0 | ... AA20: =Z20 -> 0 | AB20: =O20*1.03 -> 0
C21: Dues & Subscriptions | F21: 2070.99 | H21: =G21*4 -> 0 | I21: 2100 | J21: =I21*1.03 -> 2163 | K21: =J21*1.03 -> 2227.89 | L21: =K21*1.03 -> 2294.7267 | M21: =L21*1.03 -> 2363.5685 | O21: 2100 | P21: =O21/12 -> 175 | Q21: =P21 -> 175 | R21: =Q21 -> 175 | S21: =R21 -> 175 | T21: =S21 -> 175 | U21: =T21 -> 175 | V21: =U21 -> 175 | W21: =V21 -> 175 | X21: =W21 -> 175 | ... AA21: =Z21 -> 175 | AB21: =O21*1.03 -> 2163
C22: Administrator Expense | F22: 54623 | H22: =G22*4 -> 0 | I22: 55000 | J22: =I22*1.03 -> 56650 | K22: =J22*1.03 -> 58349.5 | L22: =K22*1.03 -> 60099.985 | M22: =L22*1.03 -> 61902.985 | O22: 55000 | P22: =O22/12 -> 4583.3333 | Q22: =P22 -> 4583.3333 | R22: =Q22 -> 4583.3333 | S22: =R22 -> 4583.3333 | T22: =S22 -> 4583.3333 | U22: =T22 -> 4583.3333 | V22: =U22 -> 4583.3333 | W22: =V22 -> 4583.3333 | X22: =W22 -> 4583.3333 | ... AA22: =Z22 -> 4583.3333 | AB22: =O22*1.03 -> 56650
C23: Employee Expenses | F23: =725+790+478809.52+720.25-54623 -> 426421.77 | H23: =G23*4 -> 0 | I23: 385000 | J23: =I23*1.03 -> 396550 | K23: =J23*1.03 -> 408446.5 | L23: =K23*1.03 -> 420699.9 | M23: =L23*1.03 -> 433320.89 | O23: 385000 | P23: =O23/12 -> 32083.333 | Q23: =P23 -> 32083.333 | R23: =Q23 -> 32083.333 | S23: =R23 -> 32083.333 | T23: =S23 -> 32083.333 | U23: =T23 -> 32083.333 | V23: =U23 -> 32083.333 | W23: =V23 -> 32083.333 | X23: =W23 -> 32083.333 | ... AA23: =Z23 -> 32083.333 | AB23: =O23*1.03 -> 396550
C24: Franchise Fees | F24: 29512 | H24: =G24*4 -> 0 | I24: 43200 | J24: =I24*1.03 -> 44496 | K24: =J24*1.03 -> 45830.88 | L24: =K24*1.03 -> 47205.806 | M24: =L24*1.03 -> 48621.981 | O24: 43200 | P24: =O24/12 -> 3600 | Q24: =P24 -> 3600 | R24: =Q24 -> 3600 | S24: =R24 -> 3600 | T24: =S24 -> 3600 | U24: =T24 -> 3600 | V24: =U24 -> 3600 | W24: =V24 -> 3600 | X24: =W24 -> 3600 | ... AA24: =Z24 -> 3600 | AB24: =O24*1.03 -> 44496
C25: Cleaning | H25: =G25*4 -> 0 | J25: =I25*1.03 -> 0 | K25: =J25*1.03 -> 0 | L25: =K25*1.03 -> 0 | M25: =L25*1.03 -> 0 | P25: =O25/12 -> 0 | Q25: =P25 -> 0 | R25: =Q25 -> 0 | S25: =R25 -> 0 | T25: =S25 -> 0 | U25: =T25 -> 0 | V25: =U25 -> 0 | W25: =V25 -> 0 | X25: =W25 -> 0 | ... AA25: =Z25 -> 0 | AB25: =O25*1.03 -> 0
C26: Household Supplies | F26: =171.62+5295.66 -> 5467.28 | H26: =G26*4 -> 0 | J26: =I26*1.03 -> 0 | K26: =J26*1.03 -> 0 | L26: =K26*1.03 -> 0 | M26: =L26*1.03 -> 0 | P26: =O26/12 -> 0 | Q26: =P26 -> 0 | R26: =Q26 -> 0 | S26: =R26 -> 0 | T26: =S26 -> 0 | U26: =T26 -> 0 | V26: =U26 -> 0 | W26: =V26 -> 0 | X26: =W26 -> 0 | ... AA26: =Z26 -> 0 | AB26: =O26*1.03 -> 0
C27: Management Fees | H27: =G27*4 -> 0 | J27: =I27*1.03 -> 0 | K27: =J27*1.03 -> 0 | L27: =K27*1.03 -> 0 | M27: =L27*1.03 -> 0 | P27: =O27/12 -> 0 | Q27: =P27 -> 0 | R27: =Q27 -> 0 | S27: =R27 -> 0 | T27: =S27 -> 0 | U27: =T27 -> 0 | V27: =U27 -> 0 | W27: =V27 -> 0 | X27: =W27 -> 0 | ... AA27: =Z27 -> 0 | AB27: =O27*1.03 -> 0
C28: General business expenses | H28: =G28*4 -> 0 | J28: =I28*1.03 -> 0 | K28: =J28*1.03 -> 0 | L28: =K28*1.03 -> 0 | M28: =L28*1.03 -> 0 | P28: =O28/12 -> 0 | Q28: =P28 -> 0 | R28: =Q28 -> 0 | S28: =R28 -> 0 | T28: =S28 -> 0 | U28: =T28 -> 0 | V28: =U28 -> 0 | W28: =V28 -> 0 | X28: =W28 -> 0 | ... AA28: =Z28 -> 0 | AB28: =O28*1.03 -> 0
C29: Insurance | F29: 13411.22 | H29: =G29*4 -> 0 | I29: 12700 | J29: =I29*1.03 -> 13081 | K29: =J29*1.03 -> 13473.43 | L29: =K29*1.03 -> 13877.633 | M29: =L29*1.03 -> 14293.962 | O29: 12700 | P29: =O29/12 -> 1058.3333 | Q29: =P29 -> 1058.3333 | R29: =Q29 -> 1058.3333 | S29: =R29 -> 1058.3333 | T29: =S29 -> 1058.3333 | U29: =T29 -> 1058.3333 | V29: =U29 -> 1058.3333 | W29: =V29 -> 1058.3333 | X29: =W29 -> 1058.3333 | ... AA29: =Z29 -> 1058.3333 | AB29: =O29*1.03 -> 13081
C30: Liability insurance | H30: =G30*4 -> 0 | J30: =I30*1.03 -> 0 | K30: =J30*1.03 -> 0 | L30: =K30*1.03 -> 0 | M30: =L30*1.03 -> 0 | P30: =O30/12 -> 0 | Q30: =P30 -> 0 | R30: =Q30 -> 0 | S30: =R30 -> 0 | T30: =S30 -> 0 | U30: =T30 -> 0 | V30: =U30 -> 0 | W30: =V30 -> 0 | X30: =W30 -> 0 | ... AA30: =Z30 -> 0 | AB30: =O30*1.03 -> 0
C31: Property insurance | H31: =G31*4 -> 0 | J31: =I31*1.03 -> 0 | K31: =J31*1.03 -> 0 | L31: =K31*1.03 -> 0 | M31: =L31*1.03 -> 0 | P31: =O31/12 -> 0 | Q31: =P31 -> 0 | R31: =Q31 -> 0 | S31: =R31 -> 0 | T31: =S31 -> 0 | U31: =T31 -> 0 | V31: =U31 -> 0 | W31: =V31 -> 0 | X31: =W31 -> 0 | ... AA31: =Z31 -> 0 | AB31: =O31*1.03 -> 0
C32: Lease Payments - Equipment | H32: =G32*4 -> 0 | J32: =I32*1.03 -> 0 | K32: =J32*1.03 -> 0 | L32: =K32*1.03 -> 0 | M32: =L32*1.03 -> 0 | P32: =O32/12 -> 0 | Q32: =P32 -> 0 | R32: =Q32 -> 0 | S32: =R32 -> 0 | T32: =S32 -> 0 | U32: =T32 -> 0 | V32: =U32 -> 0 | W32: =V32 -> 0 | X32: =W32 -> 0 | ... AA32: =Z32 -> 0 | AB32: =O32*1.03 -> 0
C33: Medical Supplies | F33: 1558.37 | H33: =G33*4 -> 0 | I33: 3500 | J33: =I33*1.03 -> 3605 | K33: =J33*1.03 -> 3713.15 | L33: =K33*1.03 -> 3824.5445 | M33: =L33*1.03 -> 3939.2808 | O33: 3500 | P33: =O33/12 -> 291.66667 | Q33: =P33 -> 291.66667 | R33: =Q33 -> 291.66667 | S33: =R33 -> 291.66667 | T33: =S33 -> 291.66667 | U33: =T33 -> 291.66667 | V33: =U33 -> 291.66667 | W33: =V33 -> 291.66667 | X33: =W33 -> 291.66667 | ... AA33: =Z33 -> 291.66667 | AB33: =O33*1.03 -> 3605
C34: Office expenses | F34: 7642.79 | H34: =G34*4 -> 0 | I34: 1500 | J34: =I34*1.03 -> 1545 | K34: =J34*1.03 -> 1591.35 | L34: =K34*1.03 -> 1639.0905 | M34: =L34*1.03 -> 1688.2632 | O34: 1500 | P34: =O34/12 -> 125 | Q34: =P34 -> 125 | R34: =Q34 -> 125 | S34: =R34 -> 125 | T34: =S34 -> 125 | U34: =T34 -> 125 | V34: =U34 -> 125 | W34: =V34 -> 125 | X34: =W34 -> 125 | ... AA34: =Z34 -> 125 | AB34: =O34*1.03 -> 1545
C35: Operations Contract Service | F35: 15182.56 | H35: =G35*4 -> 0 | J35: =I35*1.03 -> 0 | K35: =J35*1.03 -> 0 | L35: =K35*1.03 -> 0 | M35: =L35*1.03 -> 0 | P35: =O35/12 -> 0 | Q35: =P35 -> 0 | R35: =Q35 -> 0 | S35: =R35 -> 0 | T35: =S35 -> 0 | U35: =T35 -> 0 | V35: =U35 -> 0 | W35: =V35 -> 0 | X35: =W35 -> 0 | ... AA35: =Z35 -> 0 | AB35: =O35*1.03 -> 0
C36: Placement Fees | H36: =G36*4 -> 0 | J36: =I36*1.03 -> 0 | K36: =J36*1.03 -> 0 | L36: =K36*1.03 -> 0 | M36: =L36*1.03 -> 0 | P36: =O36/12 -> 0 | Q36: =P36 -> 0 | R36: =Q36 -> 0 | S36: =R36 -> 0 | T36: =S36 -> 0 | U36: =T36 -> 0 | V36: =U36 -> 0 | W36: =V36 -> 0 | X36: =W36 -> 0 | ... AA36: =Z36 -> 0 | AB36: =O36*1.03 -> 0
C37: Raw Food | F37: 49947.72 | H37: =G37*4 -> 0 | I37: 55000 | J37: =I37*1.03 -> 56650 | K37: =J37*1.03 -> 58349.5 | L37: =K37*1.03 -> 60099.985 | M37: =L37*1.03 -> 61902.985 | O37: 55000 | P37: =O37/12 -> 4583.3333 | Q37: =P37 -> 4583.3333 | R37: =Q37 -> 4583.3333 | S37: =R37 -> 4583.3333 | T37: =S37 -> 4583.3333 | U37: =T37 -> 4583.3333 | V37: =U37 -> 4583.3333 | W37: =V37 -> 4583.3333 | X37: =W37 -> 4583.3333 | ... AA37: =Z37 -> 4583.3333 | AB37: =O37*1.03 -> 56650
C38: Repairs & maintenance | F38: 26115.45 | H38: =G38*4 -> 0 | I38: 12400 | J38: =I38*1.03 -> 12772 | K38: =J38*1.03 -> 13155.16 | L38: =K38*1.03 -> 13549.815 | M38: =L38*1.03 -> 13956.309 | O38: 12400 | P38: =O38/12 -> 1033.3333 | Q38: =P38 -> 1033.3333 | R38: =Q38 -> 1033.3333 | S38: =R38 -> 1033.3333 | T38: =S38 -> 1033.3333 | U38: =T38 -> 1033.3333 | V38: =U38 -> 1033.3333 | W38: =V38 -> 1033.3333 | X38: =W38 -> 1033.3333 | ... AA38: =Z38 -> 1033.3333 | AB38: =O38*1.03 -> 12772
C39: Resident Activities | H39: =G39*4 -> 0 | I39: 750 | J39: =I39*1.03 -> 772.5 | K39: =J39*1.03 -> 795.675 | L39: =K39*1.03 -> 819.54525 | M39: =L39*1.03 -> 844.13161 | O39: 750 | P39: =O39/12 -> 62.5 | Q39: =P39 -> 62.5 | R39: =Q39 -> 62.5 | S39: =R39 -> 62.5 | T39: =S39 -> 62.5 | U39: =T39 -> 62.5 | V39: =U39 -> 62.5 | W39: =V39 -> 62.5 | X39: =W39 -> 62.5 | ... AA39: =Z39 -> 62.5 | AB39: =O39*1.03 -> 772.5
C40: Taxes paid | H40: =G40*4 -> 0 | J40: =I40*1.03 -> 0 | K40: =J40*1.03 -> 0 | L40: =K40*1.03 -> 0 | M40: =L40*1.03 -> 0 | P40: =O40/12 -> 0 | Q40: =P40 -> 0 | R40: =Q40 -> 0 | S40: =R40 -> 0 | T40: =S40 -> 0 | U40: =T40 -> 0 | V40: =U40 -> 0 | W40: =V40 -> 0 | X40: =W40 -> 0 | ... AA40: =Z40 -> 0 | AB40: =O40*1.03 -> 0
C41: Property taxes | F41: 23048.34 | H41: =G41*4 -> 0 | I41: 19900 | J41: =I41*1.03 -> 20497 | K41: =J41*1.03 -> 21111.91 | L41: =K41*1.03 -> 21745.267 | M41: =L41*1.03 -> 22397.625 | O41: 19900 | P41: =O41/12 -> 1658.3333 | Q41: =P41 -> 1658.3333 | R41: =Q41 -> 1658.3333 | S41: =R41 -> 1658.3333 | T41: =S41 -> 1658.3333 | U41: =T41 -> 1658.3333 | V41: =U41 -> 1658.3333 | W41: =V41 -> 1658.3333 | X41: =W41 -> 1658.3333 | ... AA41: =Z41 -> 1658.3333 | AB41: =O41*1.03 -> 20497
C42: Personal Property Taxes | H42: =G42*4 -> 0 | P42: =O42/12 -> 0 | Q42: =P42 -> 0 | R42: =Q42 -> 0 | S42: =R42 -> 0 | T42: =S42 -> 0 | U42: =T42 -> 0 | V42: =U42 -> 0 | W42: =V42 -> 0 | X42: =W42 -> 0 | ... AA42: =Z42 -> 0
C43: Travel/Vehicle | F43: =3963.42+6 -> 3969.42 | H43: =G43*4 -> 0 | J43: =I43*1.03 -> 0 | K43: =J43*1.03 -> 0 | L43: =K43*1.03 -> 0 | M43: =L43*1.03 -> 0 | P43: =O43/12 -> 0 | Q43: =P43 -> 0 | R43: =Q43 -> 0 | S43: =R43 -> 0 | T43: =S43 -> 0 | U43: =T43 -> 0 | V43: =U43 -> 0 | W43: =V43 -> 0 | X43: =W43 -> 0 | ... AA43: =Z43 -> 0 | AB43: =O43*1.03 -> 0
...

Sheet Proforma Combined
C2: 3 Year Historicals (Actuals)
C4: Year | D4: 2022 | E4: 2023 | F4: 2024 | G4: 2025 YTD (march) | H4: 2025 Annualized | I4: Proforma Year 1 | J4: Proforma Year 2 | K4: Proforma Year 3 | L4: Proforma Year 4 | M4: Proforma Year 5
C5: Potential Income | I5: 960000
C6: Vacancy | I6: =I5*-0.1 -> -96000
C7: Income
C8: Day Care | I8: 5000 | J8: =I8*1.2 -> 6000 | K8: =J8*1.2 -> 7200 | L8: =K8*1.2 -> 8640 | M8: =L8*1.2 -> 10368
C9: Other Income | F9: 13087.72 | I9: 2500 | J9: =I9 -> 2500 | K9: =J9 -> 2500 | L9: =K9 -> 2500 | M9: =L9 -> 2500
C10: Rental Income | F10: 835117.5 | H10: =G10*4 -> 0 | I10: =I5+I6 -> 864000 | J10: =I10*1.03 -> 889920 | K10: =J10*1.03 -> 916617.6 | L10: =K10*1.03 -> 944116.13 | M10: =L10*1.03 -> 972439.61
C11: Move In Fees | I11: 5000 | J11: =I11*1.2 -> 6000 | K11: =J11*1.2 -> 7200 | L11: =K11*1.2 -> 8640 | M11: =L11*1.2 -> 10368
C12: Total Income | D12: =SUM(D8:D11) -> 0 | E12: =SUM(E8:E11) -> 0 | F12: =SUM(F8:F11) -> 848205.22 | G12: =SUM(G8:G11) -> 0 | H12: =SUM(H8:H11) -> 0 | I12: =SUM(I8:I11) -> 876500 | J12: =SUM(J8:J11) -> 904420 | K12: =SUM(K8:K11) -> 933517.6 | ... M12: =SUM(M8:M11) -> 995675.61
C14: Expenses
C15: Accounting | F15: 8954.54 | H15: =G15*4 -> 0 | I15: 2000 | J15: =I15*1.03 -> 2060 | K15: =J15*1.03 -> 2121.8 | L15: =K15*1.03 -> 2185.454 | M15: =L15*1.03 -> 2251.0176
C16: Advertising/Promotional | F16: 252.13 | H16: =G16*4 -> 0 | I16: 600 | J16: =I16*1.03 -> 618 | K16: =J16*1.03 -> 636.54 | L16: =K16*1.03 -> 655.6362 | M16: =L16*1.03 -> 675.30529
C17: Bank Charges | F17: 3817.98 | H17: =G17*4 -> 0 | I17: 500 | J17: =I17*1.03 -> 515 | K17: =J17*1.03 -> 530.45 | L17: =K17*1.03 -> 546.3635 | M17: =L17*1.03 -> 562.75441
C18: Business licenses/Permits | F18: 1819.25 | H18: =G18*4 -> 0 | I18: 1800 | J18: =I18*1.03 -> 1854 | K18: =J18*1.03 -> 1909.62 | L18: =K18*1.03 -> 1966.9086 | M18: =L18*1.03 -> 2025.9159
C19: Nursing | H19: =G19*4 -> 0 | I19: 6720 | J19: =I19*1.03 -> 6921.6 | K19: =J19*1.03 -> 7129.248 | L19: =K19*1.03 -> 7343.1254 | M19: =L19*1.03 -> 7563.4192
C20: Dietician | H20: =G20*4 -> 0 | J20: =I20*1.03 -> 0 | K20: =J20*1.03 -> 0 | L20: =K20*1.03 -> 0 | M20: =L20*1.03 -> 0
C21: Dues & Subscriptions | F21: 2070.99 | H21: =G21*4 -> 0 | I21: 2100 | J21: =I21*1.03 -> 2163 | K21: =J21*1.03 -> 2227.89 | L21: =K21*1.03 -> 2294.7267 | M21: =L21*1.03 -> 2363.5685
C22: Administrator Expense | F22: 54623 | H22: =G22*4 -> 0 | J22: =I22*1.03 -> 0 | K22: =J22*1.03 -> 0 | L22: =K22*1.03 -> 0 | M22: =L22*1.03 -> 0
C23: Employee Expenses | F23: =725+790+478809.52+720.25-54623 -> 426421.77 | H23: =G23*4 -> 0 | I23: 430000 | J23: =I23*1.03 -> 442900 | K23: =J23*1.03 -> 456187 | L23: =K23*1.03 -> 469872.61 | M23: =L23*1.03 -> 483968.79
C24: Franchise Fees | F24: 29512 | H24: =G24*4 -> 0 | I24: 43200 | J24: =I24*1.03 -> 44496 | K24: =J24*1.03 -> 45830.88 | L24: =K24*1.03 -> 47205.806 | M24: =L24*1.03 -> 48621.981
C25: Cleaning | H25: =G25*4 -> 0 | J25: =I25*1.03 -> 0 | K25: =J25*1.03 -> 0 | L25: =K25*1.03 -> 0 | M25: =L25*1.03 -> 0
C26: Household Supplies | F26: =171.62+5295.66 -> 5467.28 | H26: =G26*4 -> 0 | J26: =I26*1.03 -> 0 | K26: =J26*1.03 -> 0 | L26: =K26*1.03 -> 0 | M26: =L26*1.03 -> 0
C27: Management Fees | H27: =G27*4 -> 0 | J27: =I27*1.03 -> 0 | K27: =J27*1.03 -> 0 | L27: =K27*1.03 -> 0 | M27: =L27*1.03 -> 0
C28: General business expenses | H28: =G28*4 -> 0 | J28: =I28*1.03 -> 0 | K28: =J28*1.03 -> 0 | L28: =K28*1.03 -> 0 | M28: =L28*1.03 -> 0
C29: Insurance | F29: 13411.22 | H29: =G29*4 -> 0 | I29: 12700 | J29: =I29*1.03 -> 13081 | K29: =J29*1.03 -> 13473.43 | L29: =K29*1.03 -> 13877.633 | M29: =L29*1.03 -> 14293.962
C30: Liability insurance | H30: =G30*4 -> 0 | J30: =I30*1.03 -> 0 | K30: =J30*1.03 -> 0 | L30: =K30*1.03 -> 0 | M30: =L30*1.03 -> 0
C31: Property insurance | H31: =G31*4 -> 0 | J31: =I31*1.03 -> 0 | K31: =J31*1.03 -> 0 | L31: =K31*1.03 -> 0 | M31: =L31*1.03 -> 0
C32: Lease Payments - Equipment | H32: =G32*4 -> 0 | J32: =I32*1.03 -> 0 | K32: =J32*1.03 -> 0 | L32: =K32*1.03 -> 0 | M32: =L32*1.03 -> 0
C33: Medical Supplies | F33: 1558.37 | H33: =G33*4 -> 0 | I33: 3500 | J33: =I33*1.03 -> 3605 | K33: =J33*1.03 -> 3713.15 | L33: =K33*1.03 -> 3824.5445 | M33: =L33*1.03 -> 3939.2808
C34: Office expenses | F34: 7642.79 | H34: =G34*4 -> 0 | I34: 5000 | J34: =I34*1.03 -> 5150 | K34: =J34*1.03 -> 5304.5 | L34: =K34*1.03 -> 5463.635 | M34: =L34*1.03 -> 5627.5441
C35: Operations Contract Service | F35: 15182.56 | H35: =G35*4 -> 0 | J35: =I35*1.03 -> 0 | K35: =J35*1.03 -> 0 | L35: =K35*1.03 -> 0 | M35: =L35*1.03 -> 0
C36: Placement Fees | H36: =G36*4 -> 0 | J36: =I36*1.03 -> 0 | K36: =J36*1.03 -> 0 | L36: =K36*1.03 -> 0 | M36: =L36*1.03 -> 0
C37: Raw Food | F37: 49947.72 | H37: =G37*4 -> 0 | I37: 55000 | J37: =I37*1.03 -> 56650 | K37: =J37*1.03 -> 58349.5 | L37: =K37*1.03 -> 60099.985 | M37: =L37*1.03 -> 61902.985
C38: Repairs & maintenance | F38: 26115.45 | H38: =G38*4 -> 0 | I38: 12400 | J38: =I38*1.03 -> 12772 | K38: =J38*1.03 -> 13155.16 | L38: =K38*1.03 -> 13549.815 | M38: =L38*1.03 -> 13956.309
C39: Resident Activities | H39: =G39*4 -> 0 | I39: 5000 | J39: =I39*1.03 -> 5150 | K39: =J39*1.03 -> 5304.5 | L39: =K39*1.03 -> 5463.635 | M39: =L39*1.03 -> 5627.5441
C40: Taxes paid | H40: =G40*4 -> 0 | J40: =I40*1.03 -> 0 | K40: =J40*1.03 -> 0 | L40: =K40*1.03 -> 0 | M40: =L40*1.03 -> 0
C41: Property taxes | F41: 23048.34 | H41: =G41*4 -> 0 | I41: 19900 | J41: =I41*1.03 -> 20497 | K41: =J41*1.03 -> 21111.91 | L41: =K41*1.03 -> 21745.267 | M41: =L41*1.03 -> 22397.625
C42: Personal Property Taxes | H42: =G42*4 -> 0 | J42: -45000 | K42: -44999 | L42: -44998 | M42: -44997
C43: Travel/Vehicle | F43: =3963.42+6 -> 3969.42 | H43: =G43*4 -> 0 | J43: =I43*1.03 -> 0 | K43: =J43*1.03 -> 0 | L43: =K43*1.03 -> 0 | M43: =L43*1.03 -> 0
...

Sheet 3 Year Proforma
C2: Proforma | J2: Actuals
D4: Year 1 | E4: Year 2 | F4: Year 3 | G4: Year 4 | H4: Year 5 | K4: =Proforma!D4 -> 2022 | L4: =Proforma!E4 -> 2023 | M4: =Proforma!F4 -> 2024 | N4: =Proforma!G4 -> 2025 YTD (march) | O4: =Proforma!H4 -> 2025 Annualized
C5: Gross Potential Rent | D5: =166554.6*12 -> 1998655.2 | E5: =D5*1.03 -> 2058614.9 | F5: =E5*1.03 -> 2120373.3
C6: Vacancy @ 5% | D6: =D5*-0.086 -> -171884.35 | E6: =E5*-0.086 -> -177040.88 | F6: =F5*-0.086 -> -182352.1
C7: Other Income | D7: =2842.28*12 -> 34107.36 | E7: =2842.28*12 -> 34107.36 | F7: =2842.28*12 -> 34107.36
C8: Effective Gross Income | D8: =Proforma!I12 -> 876500 | E8: =Proforma!J12 -> 904420 | F8: =Proforma!K12 -> 933517.6 | G8: =Proforma!L12 -> 963896.13 | H8: =Proforma!M12 -> 995675.61 | J8: =C8 -> Effective Gross Income | K8: =Proforma!D12 -> 0 | L8: =Proforma!E12 -> 0 | M8: =Proforma!F12 -> 848205.22 | N8: =Proforma!G12 -> 0 | O8: =Proforma!H12 -> 0
C9: Expenses | D9: =Proforma!I46 -> 631670 | E9: =Proforma!J46 -> 650620.1 | F9: =Proforma!K46 -> 670138.7 | G9: =Proforma!L46 -> 690242.86 | H9: =Proforma!M46 -> 710950.15 | J9: =C9 -> Expenses | K9: =Proforma!D46 -> 0 | L9: =Proforma!E46 -> 0 | M9: =Proforma!F46 -> 706323.88 | N9: =Proforma!G46 -> 0 | O9: =Proforma!H46 -> 0
C11: Net Operating Income | D11: =D8-D9 -> 244830 | E11: =E8-E9 -> 253799.9 | F11: =F8-F9 -> 263378.9 | G11: =G8-G9 -> 273653.26 | H11: =H8-H9 -> 284725.46 | J11: =C11 -> Net Operating Income | K11: =K8-K9 -> 0 | L11: =L8-L9 -> 0 | M11: =M8-M9 -> 141881.34 | N11: =N8-N9 -> 0 | O11: =O8-O9 -> 0
J13: Excluded Expenses
J14: Owner HSA
J15: Owner Life Insurance
J16: Owner Salary
J17: Owner Vehicle
J18: Owner Storage Unit
J19: Owner Short Term Interst
J20: Owner Other Income
J21: Owner Mortgage Payment
H26: =H10+H18 -> 0 | I26: =I10+I18 -> 0 | J26: =J10+J18 -> #VALUE!

Sheet Reimbursements
D1: Check | E1: Deposited to
A2: Earnest Money | B2: Cory 1031 Money
A3: Apprisal
A4: Inspection
A5: Environmental

Sheet Capital Stack
A1: Investor | B1: Amount | C1: Name/Entity | D1: Final Ownership | E1: Ownership | F1: Email | G1: Identifier | H1: Signed Docs | I1: Wire | J1: Both
D2: =E2*0.1 -> #DIV/0! | E2: =B2/$B$15 -> #DIV/0!
D3: =E3*0.1 -> #DIV/0! | E3: =B3/$B$15 -> #DIV/0!
D4: =E4*0.1 -> #DIV/0! | E4: =B4/$B$15 -> #DIV/0!
D5: =E5*0.1 -> #DIV/0! | E5: =B5/$B$15 -> #DIV/0!
D6: =E6*0.1 -> #DIV/0! | E6: =B6/$B$15 -> #DIV/0!
D7: =E7*0.1 -> #DIV/0! | E7: =B7/$B$15 -> #DIV/0!
D8: =E8*0.1 -> #DIV/0! | E8: =B8/$B$15 -> #DIV/0!
D9: =E9*0.1 -> #DIV/0! | E9: =B9/$B$15 -> #DIV/0!
D10: =E10*0.1 -> #DIV/0! | E10: =B10/$B$15 -> #DIV/0!
D11: =E11*0.1 -> #DIV/0! | E11: =B11/$B$15 -> #DIV/0!
D12: =E12*0.1 -> #DIV/0! | E12: =B12/$B$15 -> #DIV/0!
D13: 0.45
D14: 0.45
A15: Total | B15: =SUM(B2:B14) -> 0
A16: Remaining
A19: Reached out | C19: Followed up.
A20: Cam Cope | B20: Maybe | C20: 45222
A23: Bryan Griffiths | B23: Maybe | C23: 45222
A24: Alex Smith | B24: Maybe
A25: Randy Clayton
A27: Ben Clayton
A28: Jeff Meihoffer
A29: Rich Toloti | B29: Maybe
A30: Woody Klemetson
A31: Sterling Snow
A32: Blakely Cragun
A33: Adam and Andrew Law
A34: Ray Dodd
A35: Todd Orullian
A36: Adam Christensen
A37: Matt Boardman
A38: Scott Eliason
A39: Devin Deaton | B39: No
A40: Cameron Lee | B40: No
A41: Eric Motzkus | B41: No
A42: Aaron Meier | B42: No
A43: Mike Peterson | B43: No
A44: Jon Waddoups | B44: No
A45: Joel Reichert | B45: No
...
